Workbook

Sheet INTRO
A2: PURPOSE
A3: A small, inspectable discrete-event simulation of two architectures carrying the same traffic under the same link conditions, built in plain Excel formulas with no macros. Phase 1 of the Read Me handoff: agree the logic here, then translate it to MATLAB and SimEvents.
A5: THE TWO PATHS
A6: Ground-centric: observation arrives > wait for link > downlink full volume > ground processing > delivered.
A7: Bounded orbital edge: observation arrives > onboard processing (slower, reduces volume) > wait for link > downlink reduced volume > delivered to the same endpoint.
A8: Both paths use the identical arrival stream, the identical processing draws and the identical link schedule.
A10: SHEETS
A11: Settings Every input. Blue on yellow is yours to change.
A12: Arrivals Shared random streams: arrivals, processing demands, volumes.
A13: Ground_Run Event calculation for the ground path, one row per observation.
A14: Edge_Run Event calculation for the edge path, one row per observation.
A15: Replications Per-replication results for both paths, the paired difference, uptime and downtime.
... A52: Demonstration only. Every number here is a simulated test value used to prove the logic. None of it is a measurement, a benchmark, or evidence for or against any hypothesis.

Sheet Settings
A1: Settings - every input lives here
A2: Excel DES Baseline v1.2 | 19 September 2026 | Prepared by Carlo Antonio Nino, GWU D.Eng. Praxis
A3: DEMONSTRATION MODEL. All values are simulated test values, not measured observations and not research findings.
A5: Blue cells on a yellow fill are inputs. Black cells are calculated. Change nothing else.
A7: SCENARIO
A8: Entities per replication | B8: 100 | C8: Working input. The sheets are built for up to 120 rows per replication.
A9: Replications | B9: 10 | C9: Working input. The sheets are built for up to 10 replications.
A10: Scheduled assessment window (s) | B10: 6000 | C10: Used for the uptime and downtime measures.
A11: Mean time between arrivals (s) | B11: 60 | C11: Exponential, generated by inverse transform.
A12: Observation size (MB) | B12: 300 | C12: Raw volume produced by each observation.
A14: RANDOM STREAMS
A15: Base seed, arrival stream | B15: 12345 | C15: Replication seed = base seed + 1000 * replication number.
A16: Base seed, processing stream | B16: 54321 | C16: Separate stream. Both paths use the same draws.
A17: Generator multiplier a | B17: 16807 | C17: Park-Miller generator, as used in HW5.
A18: Generator modulus m | B18: 2147483647 | C18: 2^31 - 1.
A20: GROUND-CENTRIC PATH
A21: Ground processing mean time (s) | B21: 4 | C21: Processing happens after the downlink.
A23: ORBITAL EDGE PATH
A24: Onboard processing mean time (s) | B24: 12 | C24: Onboard compute is slower than the ground. The edge path must be able to lose.
A25: Output fraction after filtering | B25: 0.25 | C25: Share of raw volume still downlinked.
A27: COMMUNICATIONS LINK (identical for both paths)
A28: Link rate (Mbps) | B28: 100 | C28: Transmission time = MB * 8 / Mbps + propagation.
A29: One-way propagation delay (s) | B29: 0.02 | C29: Held separate from queueing and transmission.
A30: Link up window (s) | B30: 600 | C30: Length of each contact or available period.
A31: Link down window (s) | B31: 120 | C31: Length of each interruption.
A32: Cycle offset (s) | B32: 0 | C32: Shifts the schedule. 0 means the window starts with the link up.
A33: Cycle length (s) | B33: =B30+B31 -> 720 | C33: Up window plus down window.
A35: ANALYSIS
A36: Service deadline (s) | B36: 120 | C36: Delivered later than this counts as outside the service deadline. Drives the availability measure.
A37: Staleness limit (s) | B37: 900 | C37: Not delivered by this time counts as dropped, not delivered. Keep it above the deadline.
A38: Significance level alpha | B38: 0.05 | C38: Two-sided. 0.05 with 9 degrees of freedom gives t = 2.2622, as in HW10.
A39: Acceptable-loss margin, availability | B39: 0.02 | C39: Recorded before testing. For a preservation claim only, never for an improvement claim.
A40: Main latency statistic, selected before testing | B40: Mean | C40: Type Mean, Median or P90. This choice drives the comparison sheet.
A42: HYPOTHESIS TEXT (editable, nothing is locked into the sheet)
A43: H0 latency (NULL HYPOTHESIS) | B43: Edge processing does not reduce the selected latency measure.
A44: H1 latency | B44: Edge processing reduces the selected latency measure.
A45: H0 availability (NULL HYPOTHESIS) | B45: Edge availability is not higher than ground availability.
A46: H1 availability | B46: Edge availability is higher than ground availability.
A48: Grid limits: the run sheets are built for 120 observations per replication and 10 replications. Entries above those limits are ignored by the results sheets.

Sheet Arrivals
A1: Arrivals - shared random streams used by BOTH paths
A5: Rep | B5: Entity | C5: X arrival | D5: U arrival | E5: Interarrival (s) | F5: Arrival time (s) | G5: X service | H5: U service | I5: Ground proc time (s) | J5: Edge proc time (s) | K5: Ground volume (MB) | L5: Edge volume (MB)
A6: 1 | B6: 1 | C6: =MOD(Settings!$B$17*(Settings!$B$15+1000*A6),Settings!$B$18) -> 224289415 | D6: =MAX(C6,1)/Settings!$B$18 -> 0.1044429 | E6: =-Settings!$B$11*LN(D6) -> 135.54689 | F6: =E6 -> 135.54689 | G6: =MOD(Settings!$B$17*(Settings!$B$16+1000*A6),Settings!$B$18) -> 929780047 | H6: =MAX(G6,1)/Settings!$B$18 -> 0.43296257 | I6: =-Settings!$B$21*LN(H6) -> 3.348416 | J6: =-Settings!$B$24*LN(H6) -> 10.045248 | K6: =Settings!$B$12 -> 300 | L6: =Settings!$B$12*Settings!$B$25 -> 75
A7: 1 | B7: 2 | C7: =MOD(Settings!$B$17*C6,Settings!$B$18) -> 798397420 | D7: =MAX(C7,1)/Settings!$B$18 -> 0.37178277 | E7: =-Settings!$B$11*LN(D7) -> 59.366733 | F7: =F6+E7 -> 194.91362 | G7: =MOD(Settings!$B$17*G6,Settings!$B$18) -> 1722234357 | H7: =MAX(G7,1)/Settings!$B$18 -> 0.80197787 | I7: =-Settings!$B$21*LN(H7) -> 0.88269707 | J7: =-Settings!$B$24*LN(H7) -> 2.6480912 | K7: =Settings!$B$12 -> 300 | L7: =Settings!$B$12*Settings!$B$25 -> 75
A8: 1 | B8: 3 | C8: =MOD(Settings!$B$17*C7,Settings!$B$18) -> 1187611484 | D8: =MAX(C8,1)/Settings!$B$18 -> 0.55302469 | E8: =-Settings!$B$11*LN(D8) -> 35.541158 | F8: =F7+E8 -> 230.45478 | G8: =MOD(Settings!$B$17*G7,Settings!$B$18) -> 1808243833 | H8: =MAX(G8,1)/Settings!$B$18 -> 0.84202915 | I8: =-Settings!$B$21*LN(H8) -> 0.68776257 | J8: =-Settings!$B$24*LN(H8) -> 2.0632877 | K8: =Settings!$B$12 -> 300 | L8: =Settings!$B$12*Settings!$B$25 -> 75
A9: 1 | B9: 4 | C9: =MOD(Settings!$B$17*C8,Settings!$B$18) -> 1473196370 | D9: =MAX(C9,1)/Settings!$B$18 -> 0.68601052 | E9: =-Settings!$B$11*LN(D9) -> 22.611739 | F9: =F8+E9 -> 253.06652 | G9: =MOD(Settings!$B$17*G8,Settings!$B$18) -> 2113012534 | H9: =MAX(G9,1)/Settings!$B$18 -> 0.98394814 | I9: =-Settings!$B$21*LN(H9) -> 0.064728358 | J9: =-Settings!$B$24*LN(H9) -> 0.19418507 | K9: =Settings!$B$12 -> 300 | L9: =Settings!$B$12*Settings!$B$25 -> 75
A10: 1 | B10: 5 | C10: =MOD(Settings!$B$17*C9,Settings!$B$18) -> 1672424327 | D10: =MAX(C10,1)/Settings!$B$18 -> 0.77878327 | E10: =-Settings!$B$11*LN(D10) -> 15.00135 | F10: =F9+E10 -> 268.06787 | G10: =MOD(Settings!$B$17*G9,Settings!$B$18) -> 464588499 | H10: =MAX(G10,1)/Settings!$B$18 -> 0.21634088 | I10: =-Settings!$B$21*LN(H10) -> 6.1235999 | J10: =-Settings!$B$24*LN(H10) -> 18.3708 | K10: =Settings!$B$12 -> 300 | L10: =Settings!$B$12*Settings!$B$25 -> 75
A11: 1 | B11: 6 | C11: =MOD(Settings!$B$17*C10,Settings!$B$18) -> 22208306 | D11: =MAX(C11,1)/Settings!$B$18 -> 0.010341548 | E11: =-Settings!$B$11*LN(D11) -> 274.29514 | F11: =F10+E11 -> 542.36301 | G11: =MOD(Settings!$B$17*G10,Settings!$B$18) -> 88362201 | H11: =MAX(G11,1)/Settings!$B$18 -> 0.041146856 | I11: =-Settings!$B$21*LN(H11) -> 12.762431 | J11: =-Settings!$B$24*LN(H11) -> 38.287293 | K11: =Settings!$B$12 -> 300 | L11: =Settings!$B$12*Settings!$B$25 -> 75
A12: 1 | B12: 7 | C12: =MOD(Settings!$B$17*C11,Settings!$B$18) -> 1740328011 | D12: =MAX(C12,1)/Settings!$B$18 -> 0.81040338 | E12: =-Settings!$B$11*LN(D12) -> 12.613389 | F12: =F11+E12 -> 554.9764 | G12: =MOD(Settings!$B$17*G11,Settings!$B$18) -> 1192312130 | H12: =MAX(G12,1)/Settings!$B$18 -> 0.5552136 | I12: =-Settings!$B$21*LN(H12) -> 2.3536095 | J12: =-Settings!$B$24*LN(H12) -> 7.0608285 | K12: =Settings!$B$12 -> 300 | L12: =Settings!$B$12*Settings!$B$25 -> 75
A13: 1 | B13: 8 | C13: =MOD(Settings!$B$17*C12,Settings!$B$18) -> 965608737 | D13: =MAX(C13,1)/Settings!$B$18 -> 0.44964661 | E13: =-Settings!$B$11*LN(D13) -> 47.957599 | F13: =F12+E13 -> 602.934 | G13: =MOD(Settings!$B$17*G12,Settings!$B$18) -> 1020058753 | H13: =MAX(G13,1)/Settings!$B$18 -> 0.47500187 | I13: =-Settings!$B$21*LN(H13) -> 2.9777461 | J13: =-Settings!$B$24*LN(H13) -> 8.9332384 | K13: =Settings!$B$12 -> 300 | L13: =Settings!$B$12*Settings!$B$25 -> 75
A14: 1 | B14: 9 | C14: =MOD(Settings!$B$17*C13,Settings!$B$18) -> 452122380 | D14: =MAX(C14,1)/Settings!$B$18 -> 0.21053589 | E14: =-Settings!$B$11*LN(D14) -> 93.485949 | F14: =F13+E14 -> 696.41994 | G14: =MOD(Settings!$B$17*G13,Settings!$B$18) -> 765507670 | H14: =MAX(G14,1)/Settings!$B$18 -> 0.35646729 | I14: =-Settings!$B$21*LN(H14) -> 4.1260512 | J14: =-Settings!$B$24*LN(H14) -> 12.378154 | K14: =Settings!$B$12 -> 300 | L14: =Settings!$B$12*Settings!$B$25 -> 75
A15: 1 | B15: 10 | C15: =MOD(Settings!$B$17*C14,Settings!$B$18) -> 1023697574 | D15: =MAX(C15,1)/Settings!$B$18 -> 0.47669633 | E15: =-Settings!$B$11*LN(D15) -> 44.452537 | F15: =F14+E15 -> 740.87248 | G15: =MOD(Settings!$B$17*G14,Settings!$B$18) -> 312880513 | H15: =MAX(G15,1)/Settings!$B$18 -> 0.14569634 | I15: =-Settings!$B$21*LN(H15) -> 7.7049227 | J15: =-Settings!$B$24*LN(H15) -> 23.114768 | K15: =Settings!$B$12 -> 300 | L15: =Settings!$B$12*Settings!$B$25 -> 75
A16: 1 | B16: 11 | C16: =MOD(Settings!$B$17*C15,Settings!$B$18) -> 1793630101 | D16: =MAX(C16,1)/Settings!$B$18 -> 0.8352241 | E16: =-Settings!$B$11*LN(D16) -> 10.803312 | F16: =F15+E16 -> 751.67579 | G16: =MOD(Settings!$B$17*G15,Settings!$B$18) -> 1542814135 | H16: =MAX(G16,1)/Settings!$B$18 -> 0.71842882 | I16: =-Settings!$B$21*LN(H16) -> 1.3227546 | J16: =-Settings!$B$24*LN(H16) -> 3.9682638 | K16: =Settings!$B$12 -> 300 | L16: =Settings!$B$12*Settings!$B$25 -> 75
A17: 1 | B17: 12 | C17: =MOD(Settings!$B$17*C16,Settings!$B$18) -> 1313154568 | D17: =MAX(C17,1)/Settings!$B$18 -> 0.61148525 | E17: =-Settings!$B$11*LN(D17) -> 29.511867 | F17: =F16+E17 -> 781.18766 | G17: =MOD(Settings!$B$17*G16,Settings!$B$18) -> 1359613067 | H17: =MAX(G17,1)/Settings!$B$18 -> 0.63311917 | I17: =-Settings!$B$21*LN(H17) -> 1.8283864 | J17: =-Settings!$B$24*LN(H17) -> 5.4851593 | K17: =Settings!$B$12 -> 300 | L17: =Settings!$B$12*Settings!$B$25 -> 75
A18: 1 | B18: 13 | C18: =MOD(Settings!$B$17*C17,Settings!$B$18) -> 499384157 | D18: =MAX(C18,1)/Settings!$B$18 -> 0.23254387 | E18: =-Settings!$B$11*LN(D18) -> 87.520583 | F18: =F17+E18 -> 868.70824 | G18: =MOD(Settings!$B$17*G17,Settings!$B$18) -> 1790812989 | H18: =MAX(G18,1)/Settings!$B$18 -> 0.83391228 | I18: =-Settings!$B$21*LN(H18) -> 0.72650824 | J18: =-Settings!$B$24*LN(H18) -> 2.1795247 | K18: =Settings!$B$12 -> 300 | L18: =Settings!$B$12*Settings!$B$25 -> 75
... A125: 1 | B125: 120 | C125: =MOD(Settings!$B$17*C124,Settings!$B$18) -> 1185002360 | D125: =MAX(C125,1)/Settings!$B$18 -> 0.55180972 | E125: =-Settings!$B$11*LN(D125) -> 35.67312 | F125: =F124+E125 -> 7339.641 | G125: =MOD(Settings!$B$17*G124,Settings!$B$18) -> 787169147 | H125: =MAX(G125,1)/Settings!$B$18 -> 0.3665542 | I125: =-Settings!$B$21*LN(H125) -> 4.0144355 | J125: =-Settings!$B$24*LN(H125) -> 12.043307 | K125: =Settings!$B$12 -> 300 | L125: =Settings!$B$12*Settings!$B$25 -> 75
A126: 2 | B126: 1 | C126: =MOD(Settings!$B$17*(Settings!$B$15+1000*A126),Settings!$B$18) -> 241096415 | D126: =MAX(C126,1)/Settings!$B$18 -> 0.11226927 | E126: =-Settings!$B$11*LN(D126) -> 131.21131 | F126: =E126 -> 131.21131 | G126: =MOD(Settings!$B$17*(Settings!$B$16+1000*A126),Settings!$B$18) -> 946587047 | H126: =MAX(G126,1)/Settings!$B$18 -> 0.44078894 | I126: =-Settings!$B$21*LN(H126) -> 3.2767564 | J126: =-Settings!$B$24*LN(H126) -> 9.8302693 | K126: =Settings!$B$12 -> 300 | L126: =Settings!$B$12*Settings!$B$25 -> 75
A127: 2 | B127: 2 | C127: =MOD(Settings!$B$17*C126,Settings!$B$18) -> 1953288663 | D127: =MAX(C127,1)/Settings!$B$18 -> 0.90957091 | E127: =-Settings!$B$11*LN(D127) -> 5.6869388 | F127: =F126+E127 -> 136.89825 | G127: =MOD(Settings!$B$17*G126,Settings!$B$18) -> 729641953 | H127: =MAX(G127,1)/Settings!$B$18 -> 0.33976601 | I127: =-Settings!$B$21*LN(H127) -> 4.3179924 | J127: =-Settings!$B$24*LN(H127) -> 12.953977 | K127: =Settings!$B$12 -> 300 | L127: =Settings!$B$12*Settings!$B$25 -> 75
A128: 2 | B128: 3 | C128: =MOD(Settings!$B$17*C127,Settings!$B$18) -> 340047352 | D128: =MAX(C128,1)/Settings!$B$18 -> 0.15834689 | E128: =-Settings!$B$11*LN(D128) -> 110.57803 | F128: =F127+E128 -> 247.47628 | G128: =MOD(Settings!$B$17*G127,Settings!$B$18) -> 960679701 | H128: =MAX(G128,1)/Settings!$B$18 -> 0.44735135 | I128: =-Settings!$B$21*LN(H128) -> 3.2176439 | J128: =-Settings!$B$24*LN(H128) -> 9.6529318 | K128: =Settings!$B$12 -> 300 | L128: =Settings!$B$12*Settings!$B$25 -> 75
A129: 2 | B129: 4 | C129: =MOD(Settings!$B$17*C128,Settings!$B$18) -> 721860397 | D129: =MAX(C129,1)/Settings!$B$18 -> 0.33614244 | E129: =-Settings!$B$11*LN(D129) -> 65.413216 | F129: =F128+E129 -> 312.88949 | G129: =MOD(Settings!$B$17*G128,Settings!$B$18) -> 1361676561 | H129: =MAX(G129,1)/Settings!$B$18 -> 0.63408006 | I129: =-Settings!$B$21*LN(H129) -> 1.8223202 | J129: =-Settings!$B$24*LN(H129) -> 5.4669606 | K129: =Settings!$B$12 -> 300 | L129: =Settings!$B$12*Settings!$B$25 -> 75
A130: 2 | B130: 5 | C130: =MOD(Settings!$B$17*C129,Settings!$B$18) -> 1172570476 | D130: =MAX(C130,1)/Settings!$B$18 -> 0.54602068 | E130: =-Settings!$B$11*LN(D130) -> 36.305906 | F130: =F129+E130 -> 349.1954 | G130: =MOD(Settings!$B$17*G129,Settings!$B$18) -> 2112218295 | H130: =MAX(G130,1)/Settings!$B$18 -> 0.98357829 | I130: =-Settings!$B$21*LN(H130) -> 0.06623216 | J130: =-Settings!$B$24*LN(H130) -> 0.19869648 | K130: =Settings!$B$12 -> 300 | L130: =Settings!$B$12*Settings!$B$25 -> 75
A131: 2 | B131: 6 | C131: =MOD(Settings!$B$17*C130,Settings!$B$18) -> 2082045260 | D131: =MAX(C131,1)/Settings!$B$18 -> 0.96952788 | E131: =-Settings!$B$11*LN(D131) -> 1.8567631 | F131: =F130+E131 -> 351.05216 | G131: =MOD(Settings!$B$17*G130,Settings!$B$18) -> 715508 | H131: =MAX(G131,1)/Settings!$B$18 -> 0.00033318438 | I131: =-Settings!$B$21*LN(H131) -> 32.027258 | J131: =-Settings!$B$24*LN(H131) -> 96.081774 | K131: =Settings!$B$12 -> 300 | L131: =Settings!$B$12*Settings!$B$25 -> 75
A132: 2 | B132: 7 | C132: =MOD(Settings!$B$17*C131,Settings!$B$18) -> 1836140602 | D132: =MAX(C132,1)/Settings!$B$18 -> 0.8550196 | E132: =-Settings!$B$11*LN(D132) -> 9.3978534 | F132: =F131+E132 -> 360.45001 | G132: =MOD(Settings!$B$17*G131,Settings!$B$18) -> 1288124721 | H132: =MAX(G132,1)/Settings!$B$18 -> 0.59982982 | I132: =-Settings!$B$21*LN(H132) -> 2.0444372 | J132: =-Settings!$B$24*LN(H132) -> 6.1333116 | K132: =Settings!$B$12 -> 300 | L132: =Settings!$B$12*Settings!$B$25 -> 75
A133: 2 | B133: 8 | C133: =MOD(Settings!$B$17*C132,Settings!$B$18) -> 675090424 | D133: =MAX(C133,1)/Settings!$B$18 -> 0.31436348 | E133: =-Settings!$B$11*LN(D133) -> 69.432324 | F133: =F132+E133 -> 429.88234 | G133: =MOD(Settings!$B$17*G132,Settings!$B$18) -> 729540440 | H133: =MAX(G133,1)/Settings!$B$18 -> 0.33971874 | I133: =-Settings!$B$21*LN(H133) -> 4.3185489 | J133: =-Settings!$B$24*LN(H133) -> 12.955647 | K133: =Settings!$B$12 -> 300 | L133: =Settings!$B$12*Settings!$B$25 -> 75
A134: 2 | B134: 9 | C134: =MOD(Settings!$B$17*C133,Settings!$B$18) -> 1088649067 | D134: =MAX(C134,1)/Settings!$B$18 -> 0.50694173 | E134: =-Settings!$B$11*LN(D134) -> 40.761553 | F134: =F133+E134 -> 470.64389 | G134: =MOD(Settings!$B$17*G133,Settings!$B$18) -> 1402034357 | H134: =MAX(G134,1)/Settings!$B$18 -> 0.65287312 | I134: =-Settings!$B$21*LN(H134) -> 1.7054899 | J134: =-Settings!$B$24*LN(H134) -> 5.1164696 | K134: =Settings!$B$12 -> 300 | L134: =Settings!$B$12*Settings!$B$25 -> 75
A135: 2 | B135: 10 | C135: =MOD(Settings!$B$17*C134,Settings!$B$18) -> 364196629 | D135: =MAX(C135,1)/Settings!$B$18 -> 0.16959227 | E135: =-Settings!$B$11*LN(D135) -> 106.46149 | F135: =F134+E135 -> 577.10538 | G135: =MOD(Settings!$B$17*G134,Settings!$B$18) -> 1800863215 | H135: =MAX(G135,1)/Settings!$B$18 -> 0.83859228 | I135: =-Settings!$B$21*LN(H135) -> 0.70412258 | J135: =-Settings!$B$24*LN(H135) -> 2.1123678 | K135: =Settings!$B$12 -> 300 | L135: =Settings!$B$12*Settings!$B$25 -> 75
A136: 2 | B136: 11 | C136: =MOD(Settings!$B$17*C135,Settings!$B$18) -> 724349653 | D136: =MAX(C136,1)/Settings!$B$18 -> 0.33730159 | E136: =-Settings!$B$11*LN(D136) -> 65.206669 | F136: =F135+E136 -> 642.31205 | G136: =MOD(Settings!$B$17*G135,Settings!$B$18) -> 473533687 | H136: =MAX(G136,1)/Settings!$B$18 -> 0.22050631 | I136: =-Settings!$B$21*LN(H136) -> 6.0473159 | J136: =-Settings!$B$24*LN(H136) -> 18.141948 | K136: =Settings!$B$12 -> 300 | L136: =Settings!$B$12*Settings!$B$25 -> 75
A137: 2 | B137: 12 | C137: =MOD(Settings!$B$17*C136,Settings!$B$18) -> 59823128 | D137: =MAX(C137,1)/Settings!$B$18 -> 0.027857315 | E137: =-Settings!$B$11*LN(D137) -> 214.83958 | F137: =F136+E137 -> 857.15163 | G137: =MOD(Settings!$B$17*G136,Settings!$B$18) -> 106281627 | H137: =MAX(G137,1)/Settings!$B$18 -> 0.049491239 | I137: =-Settings!$B$21*LN(H137) -> 12.023838 | J137: =-Settings!$B$24*LN(H137) -> 36.071515 | K137: =Settings!$B$12 -> 300 | L137: =Settings!$B$12*Settings!$B$25 -> 75
A138: 2 | B138: 13 | C138: =MOD(Settings!$B$17*C137,Settings!$B$18) -> 424965500 | D138: =MAX(C138,1)/Settings!$B$18 -> 0.19788998 | E138: =-Settings!$B$11*LN(D138) -> 97.202643 | F138: =F137+E138 -> 954.35427 | G138: =MOD(Settings!$B$17*G137,Settings!$B$18) -> 1716394332 | H138: =MAX(G138,1)/Settings!$B$18 -> 0.79925839 | I138: =-Settings!$B$21*LN(H138) -> 0.89628395 | J138: =-Settings!$B$24*LN(H138) -> 2.6888519 | K138: =Settings!$B$12 -> 300 | L138: =Settings!$B$12*Settings!$B$25 -> 75
... A245: 2 | B245: 120 | C245: =MOD(Settings!$B$17*C244,Settings!$B$18) -> 2102540250 | D245: =MAX(C245,1)/Settings!$B$18 -> 0.9790716 | E245: =-Settings!$B$11*LN(D245) -> 1.2690302 | F245: =F244+E245 -> 7157.0812 | G245: =MOD(Settings!$B$17*G244,Settings!$B$18) -> 1704707037 | H245: =MAX(G245,1)/Settings!$B$18 -> 0.79381607 | I245: =-Settings!$B$21*LN(H245) -> 0.92361396 | J245: =-Settings!$B$24*LN(H245) -> 2.7708419 | K245: =Settings!$B$12 -> 300 | L245: =Settings!$B$12*Settings!$B$25 -> 75
A246: 3 | B246: 1 | C246: =MOD(Settings!$B$17*(Settings!$B$15+1000*A246),Settings!$B$18) -> 257903415 | D246: =MAX(C246,1)/Settings!$B$18 -> 0.12009564 | E246: =-Settings!$B$11*LN(D246) -> 127.16801 | F246: =E246 -> 127.16801 | G246: =MOD(Settings!$B$17*(Settings!$B$16+1000*A246),Settings!$B$18) -> 963394047 | H246: =MAX(G246,1)/Settings!$B$18 -> 0.44861531 | I246: =-Settings!$B$21*LN(H246) -> 3.2063581 | J246: =-Settings!$B$24*LN(H246) -> 9.6190743 | K246: =Settings!$B$12 -> 300 | L246: =Settings!$B$12*Settings!$B$25 -> 75
A247: 3 | B247: 2 | C247: =MOD(Settings!$B$17*C246,Settings!$B$18) -> 960696259 | D247: =MAX(C247,1)/Settings!$B$18 -> 0.44735906 | E247: =-Settings!$B$11*LN(D247) -> 48.263625 | F247: =F246+E247 -> 175.43164 | G247: =MOD(Settings!$B$17*G246,Settings!$B$18) -> 1884533196 | H247: =MAX(G247,1)/Settings!$B$18 -> 0.87755415 | I247: =-Settings!$B$21*LN(H247) -> 0.52246644 | J247: =-Settings!$B$24*LN(H247) -> 1.5673993 | K247: =Settings!$B$12 -> 300 | L247: =Settings!$B$12*Settings!$B$25 -> 75
A248: 3 | B248: 3 | C248: =MOD(Settings!$B$17*C247,Settings!$B$18) -> 1639966867 | D248: =MAX(C248,1)/Settings!$B$18 -> 0.76366908 | E248: =-Settings!$B$11*LN(D248) -> 16.177243 | F248: =F247+E248 -> 191.60888 | G248: =MOD(Settings!$B$17*G247,Settings!$B$18) -> 113115569 | H248: =MAX(G248,1)/Settings!$B$18 -> 0.052673541 | I248: =-Settings!$B$21*LN(H248) -> 11.774568 | J248: =-Settings!$B$24*LN(H248) -> 35.323704 | K248: =Settings!$B$12 -> 300 | L248: =Settings!$B$12*Settings!$B$25 -> 75
A249: 3 | B249: 4 | C249: =MOD(Settings!$B$17*C248,Settings!$B$18) -> 2118008071 | D249: =MAX(C249,1)/Settings!$B$18 -> 0.98627437 | E249: =-Settings!$B$11*LN(D249) -> 0.82924213 | F249: =F248+E249 -> 192.43812 | G249: =MOD(Settings!$B$17*G248,Settings!$B$18) -> 610340588 | H249: =MAX(G249,1)/Settings!$B$18 -> 0.28421198 | I249: =-Settings!$B$21*LN(H249) -> 5.0321396 | J249: =-Settings!$B$24*LN(H249) -> 15.096419 | K249: =Settings!$B$12 -> 300 | L249: =Settings!$B$12*Settings!$B$25 -> 75
A250: 3 | B250: 5 | C250: =MOD(Settings!$B$17*C249,Settings!$B$18) -> 672716625 | D250: =MAX(C250,1)/Settings!$B$18 -> 0.31325809 | E250: =-Settings!$B$11*LN(D250) -> 69.643672 | F250: =F249+E250 -> 262.08179 | G250: =MOD(Settings!$B$17*G249,Settings!$B$18) -> 1612364444 | H250: =MAX(G250,1)/Settings!$B$18 -> 0.7508157 | I250: =-Settings!$B$21*LN(H250) -> 1.1463802 | J250: =-Settings!$B$24*LN(H250) -> 3.4391407 | K250: =Settings!$B$12 -> 300 | L250: =Settings!$B$12*Settings!$B$25 -> 75
A251: 3 | B251: 6 | C251: =MOD(Settings!$B$17*C250,Settings!$B$18) -> 1994398567 | D251: =MAX(C251,1)/Settings!$B$18 -> 0.9287142 | E251: =-Settings!$B$11*LN(D251) -> 4.4372535 | F251: =F250+E251 -> 266.51905 | G251: =MOD(Settings!$B$17*G250,Settings!$B$18) -> 2060552462 | H251: =MAX(G251,1)/Settings!$B$18 -> 0.95951951 | I251: =-Settings!$B$21*LN(H251) -> 0.16529051 | J251: =-Settings!$B$24*LN(H251) -> 0.49587153 | K251: =Settings!$B$12 -> 300 | L251: =Settings!$B$12*Settings!$B$25 -> 75
A252: 3 | B252: 7 | C252: =MOD(Settings!$B$17*C251,Settings!$B$18) -> 1931953193 | D252: =MAX(C252,1)/Settings!$B$18 -> 0.89963581 | E252: =-Settings!$B$11*LN(D252) -> 6.3459151 | F252: =F251+E252 -> 272.86496 | G252: =MOD(Settings!$B$17*G251,Settings!$B$18) -> 1383937312 | H252: =MAX(G252,1)/Settings!$B$18 -> 0.64444603 | I252: =-Settings!$B$21*LN(H252) -> 1.7574568 | J252: =-Settings!$B$24*LN(H252) -> 5.2723704 | K252: =Settings!$B$12 -> 300 | L252: =Settings!$B$12*Settings!$B$25 -> 75
A253: 3 | B253: 8 | C253: =MOD(Settings!$B$17*C252,Settings!$B$18) -> 384572111 | D253: =MAX(C253,1)/Settings!$B$18 -> 0.17908034 | E253: =-Settings!$B$11*LN(D253) -> 103.19524 | F253: =F252+E253 -> 376.06021 | G253: =MOD(Settings!$B$17*G252,Settings!$B$18) -> 439022127 | H253: =MAX(G253,1)/Settings!$B$18 -> 0.20443561 | I253: =-Settings!$B$21*LN(H253) -> 6.3500089 | J253: =-Settings!$B$24*LN(H253) -> 19.050027 | K253: =Settings!$B$12 -> 300 | L253: =Settings!$B$12*Settings!$B$25 -> 75
A254: 3 | B254: 9 | C254: =MOD(Settings!$B$17*C253,Settings!$B$18) -> 1725175754 | D254: =MAX(C254,1)/Settings!$B$18 -> 0.80334756 | E254: =-Settings!$B$11*LN(D254) -> 13.13807 | F254: =F253+E254 -> 389.19828 | G254: =MOD(Settings!$B$17*G253,Settings!$B$18) -> 2038561044 | H254: =MAX(G254,1)/Settings!$B$18 -> 0.94927896 | I254: =-Settings!$B$21*LN(H254) -> 0.20821029 | J254: =-Settings!$B$24*LN(H254) -> 0.62463086 | K254: =Settings!$B$12 -> 300 | L254: =Settings!$B$12*Settings!$B$25 -> 75
A255: 3 | B255: 10 | C255: =MOD(Settings!$B$17*C254,Settings!$B$18) -> 1852179331 | D255: =MAX(C255,1)/Settings!$B$18 -> 0.86248821 | E255: =-Settings!$B$11*LN(D255) -> 8.8760278 | F255: =F254+E255 -> 398.0743 | G255: =MOD(Settings!$B$17*G254,Settings!$B$18) -> 1141362270 | H255: =MAX(G255,1)/Settings!$B$18 -> 0.53148822 | I255: =-Settings!$B$21*LN(H255) -> 2.5282969 | J255: =-Settings!$B$24*LN(H255) -> 7.5848908 | K255: =Settings!$B$12 -> 300 | L255: =Settings!$B$12*Settings!$B$25 -> 75
...

Sheet RGS_Ground_Run
A1: Ground_Run - arrive > wait for link > downlink full volume > ground processing > delivered
A5: Rep | B5: Entity | C5: Arrival (s) | D5: Volume (MB) | E5: Transmit time (s) | F5: Link ready (s) | G5: Link free at (s) | H5: Earliest link start (s) | I5: Cycle phase (s) | J5: Link start (s) | K5: Link done (s) | L5: Processor ready (s) | M5: Processor free at (s) | N5: Processor start (s) | O5: Processing time (s) | P5: Delivered (s) | Q5: End-to-end latency (s) | R5: Wait in link queue (s) | S5: Wait for link recovery (s) | T5: Wait for processor (s) | U5: Total queueing delay (s) | V5: Link state at arrival | W5: Delivered flag | X5: Within deadline
A6: 1 | B6: 1 | C6: =Arrivals!F6 -> 135.54689 | D6: =Arrivals!K6 -> 300 | E6: =D6*8/Settings!$B$28+Settings!$B$29 -> 24.02 | F6: =C6 -> 135.54689 | G6: 0 | H6: =MAX(F6,G6) -> 135.54689 | I6: =MOD(H6-Settings!$B$32,Settings!$B$33) -> 135.54689 | J6: =IF(I6<Settings!$B$30,IF(Settings!$B$30-I6>=E6,H6,H6+(Settings!$B$30-I6)+Settings!$B$31),H6+(Settings!$B$33-I6)) -> 135.54689 | K6: =J6+E6 -> 159.56689 | L6: =K6 -> 159.56689 | M6: 0 | N6: =MAX(L6,M6) -> 159.56689 | O6: =Arrivals!I6 -> 3.348416 | P6: =N6+O6 -> 162.9153 | Q6: =P6-C6 -> 27.368416 | R6: =H6-F6 -> 0 | S6: =J6-H6 -> 0 | T6: =N6-L6 -> 0 | U6: =R6+S6+T6 -> 0 | V6: =IF(MOD(C6-Settings!$B$32,Settings!$B$33)<Settings!$B$30,"Up","Down") -> Up | W6: =IF(OR(E6>Settings!$B$30,Q6>Settings!$B$37),0,1) -> 1 | X6: =IF(AND(W6=1,Q6<=Settings!$B$36),1,0) -> 1
A7: 1 | B7: 2 | C7: =Arrivals!F7 -> 194.91362 | D7: =Arrivals!K7 -> 300 | E7: =D7*8/Settings!$B$28+Settings!$B$29 -> 24.02 | F7: =C7 -> 194.91362 | G7: =K6 -> 159.56689 | H7: =MAX(F7,G7) -> 194.91362 | I7: =MOD(H7-Settings!$B$32,Settings!$B$33) -> 194.91362 | J7: =IF(I7<Settings!$B$30,IF(Settings!$B$30-I7>=E7,H7,H7+(Settings!$B$30-I7)+Settings!$B$31),H7+(Settings!$B$33-I7)) -> 194.91362 | K7: =J7+E7 -> 218.93362 | L7: =K7 -> 218.93362 | M7: =P6 -> 162.9153 | N7: =MAX(L7,M7) -> 218.93362 | O7: =Arrivals!I7 -> 0.88269707 | P7: =N7+O7 -> 219.81632 | Q7: =P7-C7 -> 24.902697 | R7: =H7-F7 -> 0 | S7: =J7-H7 -> 0 | T7: =N7-L7 -> 0 | U7: =R7+S7+T7 -> 0 | V7: =IF(MOD(C7-Settings!$B$32,Settings!$B$33)<Settings!$B$30,"Up","Down") -> Up | W7: =IF(OR(E7>Settings!$B$30,Q7>Settings!$B$37),0,1) -> 1 | X7: =IF(AND(W7=1,Q7<=Settings!$B$36),1,0) -> 1
A8: 1 | B8: 3 | C8: =Arrivals!F8 -> 230.45478 | D8: =Arrivals!K8 -> 300 | E8: =D8*8/Settings!$B$28+Settings!$B$29 -> 24.02 | F8: =C8 -> 230.45478 | G8: =K7 -> 218.93362 | H8: =MAX(F8,G8) -> 230.45478 | I8: =MOD(H8-Settings!$B$32,Settings!$B$33) -> 230.45478 | J8: =IF(I8<Settings!$B$30,IF(Settings!$B$30-I8>=E8,H8,H8+(Settings!$B$30-I8)+Settings!$B$31),H8+(Settings!$B$33-I8)) -> 230.45478 | K8: =J8+E8 -> 254.47478 | L8: =K8 -> 254.47478 | M8: =P7 -> 219.81632 | N8: =MAX(L8,M8) -> 254.47478 | O8: =Arrivals!I8 -> 0.68776257 | P8: =N8+O8 -> 255.16254 | Q8: =P8-C8 -> 24.707763 | R8: =H8-F8 -> 0 | S8: =J8-H8 -> 0 | T8: =N8-L8 -> 0 | U8: =R8+S8+T8 -> 0 | V8: =IF(MOD(C8-Settings!$B$32,Settings!$B$33)<Settings!$B$30,"Up","Down") -> Up | W8: =IF(OR(E8>Settings!$B$30,Q8>Settings!$B$37),0,1) -> 1 | X8: =IF(AND(W8=1,Q8<=Settings!$B$36),1,0) -> 1
A9: 1 | B9: 4 | C9: =Arrivals!F9 -> 253.06652 | D9: =Arrivals!K9 -> 300 | E9: =D9*8/Settings!$B$28+Settings!$B$29 -> 24.02 | F9: =C9 -> 253.06652 | G9: =K8 -> 254.47478 | H9: =MAX(F9,G9) -> 254.47478 | I9: =MOD(H9-Settings!$B$32,Settings!$B$33) -> 254.47478 | J9: =IF(I9<Settings!$B$30,IF(Settings!$B$30-I9>=E9,H9,H9+(Settings!$B$30-I9)+Settings!$B$31),H9+(Settings!$B$33-I9)) -> 254.47478 | K9: =J9+E9 -> 278.49478 | L9: =K9 -> 278.49478 | M9: =P8 -> 255.16254 | N9: =MAX(L9,M9) -> 278.49478 | O9: =Arrivals!I9 -> 0.064728358 | P9: =N9+O9 -> 278.55951 | Q9: =P9-C9 -> 25.492989 | R9: =H9-F9 -> 1.4082609 | S9: =J9-H9 -> 0 | T9: =N9-L9 -> 0 | U9: =R9+S9+T9 -> 1.4082609 | V9: =IF(MOD(C9-Settings!$B$32,Settings!$B$33)<Settings!$B$30,"Up","Down") -> Up | W9: =IF(OR(E9>Settings!$B$30,Q9>Settings!$B$37),0,1) -> 1 | X9: =IF(AND(W9=1,Q9<=Settings!$B$36),1,0) -> 1
A10: 1 | B10: 5 | C10: =Arrivals!F10 -> 268.06787 | D10: =Arrivals!K10 -> 300 | E10: =D10*8/Settings!$B$28+Settings!$B$29 -> 24.02 | F10: =C10 -> 268.06787 | G10: =K9 -> 278.49478 | H10: =MAX(F10,G10) -> 278.49478 | I10: =MOD(H10-Settings!$B$32,Settings!$B$33) -> 278.49478 | J10: =IF(I10<Settings!$B$30,IF(Settings!$B$30-I10>=E10,H10,H10+(Settings!$B$30-I10)+Settings!$B$31),H10+(Settings!$B$33-I10)) -> 278.49478 | K10: =J10+E10 -> 302.51478 | L10: =K10 -> 302.51478 | M10: =P9 -> 278.55951 | N10: =MAX(L10,M10) -> 302.51478 | O10: =Arrivals!I10 -> 6.1235999 | P10: =N10+O10 -> 308.63838 | Q10: =P10-C10 -> 40.570511 | R10: =H10-F10 -> 10.426911 | S10: =J10-H10 -> 0 | T10: =N10-L10 -> 0 | U10: =R10+S10+T10 -> 10.426911 | V10: =IF(MOD(C10-Settings!$B$32,Settings!$B$33)<Settings!$B$30,"Up","Down") -> Up | W10: =IF(OR(E10>Settings!$B$30,Q10>Settings!$B$37),0,1) -> 1 | X10: =IF(AND(W10=1,Q10<=Settings!$B$36),1,0) -> 1
A11: 1 | B11: 6 | C11: =Arrivals!F11 -> 542.36301 | D11: =Arrivals!K11 -> 300 | E11: =D11*8/Settings!$B$28+Settings!$B$29 -> 24.02 | F11: =C11 -> 542.36301 | G11: =K10 -> 302.51478 | H11: =MAX(F11,G11) -> 542.36301 | I11: =MOD(H11-Settings!$B$32,Settings!$B$33) -> 542.36301 | J11: =IF(I11<Settings!$B$30,IF(Settings!$B$30-I11>=E11,H11,H11+(Settings!$B$30-I11)+Settings!$B$31),H11+(Settings!$B$33-I11)) -> 542.36301 | K11: =J11+E11 -> 566.38301 | L11: =K11 -> 566.38301 | M11: =P10 -> 308.63838 | N11: =MAX(L11,M11) -> 566.38301 | O11: =Arrivals!I11 -> 12.762431 | P11: =N11+O11 -> 579.14544 | Q11: =P11-C11 -> 36.782431 | R11: =H11-F11 -> 0 | S11: =J11-H11 -> 0 | T11: =N11-L11 -> 0 | U11: =R11+S11+T11 -> 0 | V11: =IF(MOD(C11-Settings!$B$32,Settings!$B$33)<Settings!$B$30,"Up","Down") -> Up | W11: =IF(OR(E11>Settings!$B$30,Q11>Settings!$B$37),0,1) -> 1 | X11: =IF(AND(W11=1,Q11<=Settings!$B$36),1,0) -> 1
A12: 1 | B12: 7 | C12: =Arrivals!F12 -> 554.9764 | D12: =Arrivals!K12 -> 300 | E12: =D12*8/Settings!$B$28+Settings!$B$29 -> 24.02 | F12: =C12 -> 554.9764 | G12: =K11 -> 566.38301 | H12: =MAX(F12,G12) -> 566.38301 | I12: =MOD(H12-Settings!$B$32,Settings!$B$33) -> 566.38301 | J12: =IF(I12<Settings!$B$30,IF(Settings!$B$30-I12>=E12,H12,H12+(Settings!$B$30-I12)+Settings!$B$31),H12+(Settings!$B$33-I12)) -> 566.38301 | K12: =J12+E12 -> 590.40301 | L12: =K12 -> 590.40301 | M12: =P11 -> 579.14544 | N12: =MAX(L12,M12) -> 590.40301 | O12: =Arrivals!I12 -> 2.3536095 | P12: =N12+O12 -> 592.75662 | Q12: =P12-C12 -> 37.78022 | R12: =H12-F12 -> 11.406611 | S12: =J12-H12 -> 0 | T12: =N12-L12 -> 0 | U12: =R12+S12+T12 -> 11.406611 | V12: =IF(MOD(C12-Settings!$B$32,Settings!$B$33)<Settings!$B$30,"Up","Down") -> Up | W12: =IF(OR(E12>Settings!$B$30,Q12>Settings!$B$37),0,1) -> 1 | X12: =IF(AND(W12=1,Q12<=Settings!$B$36),1,0) -> 1
A13: 1 | B13: 8 | C13: =Arrivals!F13 -> 602.934 | D13: =Arrivals!K13 -> 300 | E13: =D13*8/Settings!$B$28+Settings!$B$29 -> 24.02 | F13: =C13 -> 602.934 | G13: =K12 -> 590.40301 | H13: =MAX(F13,G13) -> 602.934 | I13: =MOD(H13-Settings!$B$32,Settings!$B$33) -> 602.934 | J13: =IF(I13<Settings!$B$30,IF(Settings!$B$30-I13>=E13,H13,H13+(Settings!$B$30-I13)+Settings!$B$31),H13+(Settings!$B$33-I13)) -> 720 | K13: =J13+E13 -> 744.02 | L13: =K13 -> 744.02 | M13: =P12 -> 592.75662 | N13: =MAX(L13,M13) -> 744.02 | O13: =Arrivals!I13 -> 2.9777461 | P13: =N13+O13 -> 746.99775 | Q13: =P13-C13 -> 144.06375 | R13: =H13-F13 -> 0 | S13: =J13-H13 -> 117.066 | T13: =N13-L13 -> 0 | U13: =R13+S13+T13 -> 117.066 | V13: =IF(MOD(C13-Settings!$B$32,Settings!$B$33)<Settings!$B$30,"Up","Down") -> Down | W13: =IF(OR(E13>Settings!$B$30,Q13>Settings!$B$37),0,1) -> 1 | X13: =IF(AND(W13=1,Q13<=Settings!$B$36),1,0) -> 0
A14: 1 | B14: 9 | C14: =Arrivals!F14 -> 696.41994 | D14: =Arrivals!K14 -> 300 | E14: =D14*8/Settings!$B$28+Settings!$B$29 -> 24.02 | F14: =C14 -> 696.41994 | G14: =K13 -> 744.02 | H14: =MAX(F14,G14) -> 744.02 | I14: =MOD(H14-Settings!$B$32,Settings!$B$33) -> 24.02 | J14: =IF(I14<Settings!$B$30,IF(Settings!$B$30-I14>=E14,H14,H14+(Settings!$B$30-I14)+Settings!$B$31),H14+(Settings!$B$33-I14)) -> 744.02 | K14: =J14+E14 -> 768.04 | L14: =K14 -> 768.04 | M14: =P13 -> 746.99775 | N14: =MAX(L14,M14) -> 768.04 | O14: =Arrivals!I14 -> 4.1260512 | P14: =N14+O14 -> 772.16605 | Q14: =P14-C14 -> 75.746107 | R14: =H14-F14 -> 47.600056 | S14: =J14-H14 -> 0 | T14: =N14-L14 -> 0 | U14: =R14+S14+T14 -> 47.600056 | V14: =IF(MOD(C14-Settings!$B$32,Settings!$B$33)<Settings!$B$30,"Up","Down") -> Down | W14: =IF(OR(E14>Settings!$B$30,Q14>Settings!$B$37),0,1) -> 1 | X14: =IF(AND(W14=1,Q14<=Settings!$B$36),1,0) -> 1
A15: 1 | B15: 10 | C15: =Arrivals!F15 -> 740.87248 | D15: =Arrivals!K15 -> 300 | E15: =D15*8/Settings!$B$28+Settings!$B$29 -> 24.02 | F15: =C15 -> 740.87248 | G15: =K14 -> 768.04 | H15: =MAX(F15,G15) -> 768.04 | I15: =MOD(H15-Settings!$B$32,Settings!$B$33) -> 48.04 | J15: =IF(I15<Settings!$B$30,IF(Settings!$B$30-I15>=E15,H15,H15+(Settings!$B$30-I15)+Settings!$B$31),H15+(Settings!$B$33-I15)) -> 768.04 | K15: =J15+E15 -> 792.06 | L15: =K15 -> 792.06 | M15: =P14 -> 772.16605 | N15: =MAX(L15,M15) -> 792.06 | O15: =Arrivals!I15 -> 7.7049227 | P15: =N15+O15 -> 799.76492 | Q15: =P15-C15 -> 58.892442 | R15: =H15-F15 -> 27.167519 | S15: =J15-H15 -> 0 | T15: =N15-L15 -> 0 | U15: =R15+S15+T15 -> 27.167519 | V15: =IF(MOD(C15-Settings!$B$32,Settings!$B$33)<Settings!$B$30,"Up","Down") -> Up | W15: =IF(OR(E15>Settings!$B$30,Q15>Settings!$B$37),0,1) -> 1 | X15: =IF(AND(W15=1,Q15<=Settings!$B$36),1,0) -> 1
A16: 1 | B16: 11 | C16: =Arrivals!F16 -> 751.67579 | D16: =Arrivals!K16 -> 300 | E16: =D16*8/Settings!$B$28+Settings!$B$29 -> 24.02 | F16: =C16 -> 751.67579 | G16: =K15 -> 792.06 | H16: =MAX(F16,G16) -> 792.06 | I16: =MOD(H16-Settings!$B$32,Settings!$B$33) -> 72.06 | J16: =IF(I16<Settings!$B$30,IF(Settings!$B$30-I16>=E16,H16,H16+(Settings!$B$30-I16)+Settings!$B$31),H16+(Settings!$B$33-I16)) -> 792.06 | K16: =J16+E16 -> 816.08 | L16: =K16 -> 816.08 | M16: =P15 -> 799.76492 | N16: =MAX(L16,M16) -> 816.08 | O16: =Arrivals!I16 -> 1.3227546 | P16: =N16+O16 -> 817.40275 | Q16: =P16-C16 -> 65.726962 | R16: =H16-F16 -> 40.384207 | S16: =J16-H16 -> 0 | T16: =N16-L16 -> 0 | U16: =R16+S16+T16 -> 40.384207 | V16: =IF(MOD(C16-Settings!$B$32,Settings!$B$33)<Settings!$B$30,"Up","Down") -> Up | W16: =IF(OR(E16>Settings!$B$30,Q16>Settings!$B$37),0,1) -> 1 | X16: =IF(AND(W16=1,Q16<=Settings!$B$36),1,0) -> 1
A17: 1 | B17: 12 | C17: =Arrivals!F17 -> 781.18766 | D17: =Arrivals!K17 -> 300 | E17: =D17*8/Settings!$B$28+Settings!$B$29 -> 24.02 | F17: =C17 -> 781.18766 | G17: =K16 -> 816.08 | H17: =MAX(F17,G17) -> 816.08 | I17: =MOD(H17-Settings!$B$32,Settings!$B$33) -> 96.08 | J17: =IF(I17<Settings!$B$30,IF(Settings!$B$30-I17>=E17,H17,H17+(Settings!$B$30-I17)+Settings!$B$31),H17+(Settings!$B$33-I17)) -> 816.08 | K17: =J17+E17 -> 840.1 | L17: =K17 -> 840.1 | M17: =P16 -> 817.40275 | N17: =MAX(L17,M17) -> 840.1 | O17: =Arrivals!I17 -> 1.8283864 | P17: =N17+O17 -> 841.92839 | Q17: =P17-C17 -> 60.740726 | R17: =H17-F17 -> 34.89234 | S17: =J17-H17 -> 0 | T17: =N17-L17 -> 0 | U17: =R17+S17+T17 -> 34.89234 | V17: =IF(MOD(C17-Settings!$B$32,Settings!$B$33)<Settings!$B$30,"Up","Down") -> Up | W17: =IF(OR(E17>Settings!$B$30,Q17>Settings!$B$37),0,1) -> 1 | X17: =IF(AND(W17=1,Q17<=Settings!$B$36),1,0) -> 1
A18: 1 | B18: 13 | C18: =Arrivals!F18 -> 868.70824 | D18: =Arrivals!K18 -> 300 | E18: =D18*8/Settings!$B$28+Settings!$B$29 -> 24.02 | F18: =C18 -> 868.70824 | G18: =K17 -> 840.1 | H18: =MAX(F18,G18) -> 868.70824 | I18: =MOD(H18-Settings!$B$32,Settings!$B$33) -> 148.70824 | J18: =IF(I18<Settings!$B$30,IF(Settings!$B$30-I18>=E18,H18,H18+(Settings!$B$30-I18)+Settings!$B$31),H18+(Settings!$B$33-I18)) -> 868.70824 | K18: =J18+E18 -> 892.72824 | L18: =K18 -> 892.72824 | M18: =P17 -> 841.92839 | N18: =MAX(L18,M18) -> 892.72824 | O18: =Arrivals!I18 -> 0.72650824 | P18: =N18+O18 -> 893.45475 | Q18: =P18-C18 -> 24.746508 | R18: =H18-F18 -> 0 | S18: =J18-H18 -> 0 | T18: =N18-L18 -> 0 | U18: =R18+S18+T18 -> 0 | V18: =IF(MOD(C18-Settings!$B$32,Settings!$B$33)<Settings!$B$30,"Up","Down") -> Up | W18: =IF(OR(E18>Settings!$B$30,Q18>Settings!$B$37),0,1) -> 1 | X18: =IF(AND(W18=1,Q18<=Settings!$B$36),1,0) -> 1
... A125: 1 | B125: 120 | C125: =Arrivals!F125 -> 7339.641 | D125: =Arrivals!K125 -> 300 | E125: =D125*8/Settings!$B$28+Settings!$B$29 -> 24.02 | F125: =C125 -> 7339.641 | G125: =K124 -> 7338.9572 | H125: =MAX(F125,G125) -> 7339.641 | I125: =MOD(H125-Settings!$B$32,Settings!$B$33) -> 139.64099 | J125: =IF(I125<Settings!$B$30,IF(Settings!$B$30-I125>=E125,H125,H125+(Settings!$B$30-I125)+Settings!$B$31),H125+(Settings!$B$33-I125)) -> 7339.641 | K125: =J125+E125 -> 7363.661 | L125: =K125 -> 7363.661 | M125: =P124 -> 7341.9763 | N125: =MAX(L125,M125) -> 7363.661 | O125: =Arrivals!I125 -> 4.0144355 | P125: =N125+O125 -> 7367.6754 | Q125: =P125-C125 -> 28.034436 | R125: =H125-F125 -> 0 | S125: =J125-H125 -> 0 | T125: =N125-L125 -> 0 | U125: =R125+S125+T125 -> 0 | V125: =IF(MOD(C125-Settings!$B$32,Settings!$B$33)<Settings!$B$30,"Up","Down") -> Up | W125: =IF(OR(E125>Settings!$B$30,Q125>Settings!$B$37),0,1) -> 1 | X125: =IF(AND(W125=1,Q125<=Settings!$B$36),1,0) -> 1
A126: 2 | B126: 1 | C126: =Arrivals!F126 -> 131.21131 | D126: =Arrivals!K126 -> 300 | E126: =D126*8/Settings!$B$28+Settings!$B$29 -> 24.02 | F126: =C126 -> 131.21131 | G126: 0 | H126: =MAX(F126,G126) -> 131.21131 | I126: =MOD(H126-Settings!$B$32,Settings!$B$33) -> 131.21131 | J126: =IF(I126<Settings!$B$30,IF(Settings!$B$30-I126>=E126,H126,H126+(Settings!$B$30-I126)+Settings!$B$31),H126+(Settings!$B$33-I126)) -> 131.21131 | K126: =J126+E126 -> 155.23131 | L126: =K126 -> 155.23131 | M126: 0 | N126: =MAX(L126,M126) -> 155.23131 | O126: =Arrivals!I126 -> 3.2767564 | P126: =N126+O126 -> 158.50806 | Q126: =P126-C126 -> 27.296756 | R126: =H126-F126 -> 0 | S126: =J126-H126 -> 0 | T126: =N126-L126 -> 0 | U126: =R126+S126+T126 -> 0 | V126: =IF(MOD(C126-Settings!$B$32,Settings!$B$33)<Settings!$B$30,"Up","Down") -> Up | W126: =IF(OR(E126>Settings!$B$30,Q126>Settings!$B$37),0,1) -> 1 | X126: =IF(AND(W126=1,Q126<=Settings!$B$36),1,0) -> 1
A127: 2 | B127: 2 | C127: =Arrivals!F127 -> 136.89825 | D127: =Arrivals!K127 -> 300 | E127: =D127*8/Settings!$B$28+Settings!$B$29 -> 24.02 | F127: =C127 -> 136.89825 | G127: =K126 -> 155.23131 | H127: =MAX(F127,G127) -> 155.23131 | I127: =MOD(H127-Settings!$B$32,Settings!$B$33) -> 155.23131 | J127: =IF(I127<Settings!$B$30,IF(Settings!$B$30-I127>=E127,H127,H127+(Settings!$B$30-I127)+Settings!$B$31),H127+(Settings!$B$33-I127)) -> 155.23131 | K127: =J127+E127 -> 179.25131 | L127: =K127 -> 179.25131 | M127: =P126 -> 158.50806 | N127: =MAX(L127,M127) -> 179.25131 | O127: =Arrivals!I127 -> 4.3179924 | P127: =N127+O127 -> 183.5693 | Q127: =P127-C127 -> 46.671054 | R127: =H127-F127 -> 18.333061 | S127: =J127-H127 -> 0 | T127: =N127-L127 -> 0 | U127: =R127+S127+T127 -> 18.333061 | V127: =IF(MOD(C127-Settings!$B$32,Settings!$B$33)<Settings!$B$30,"Up","Down") -> Up | W127: =IF(OR(E127>Settings!$B$30,Q127>Settings!$B$37),0,1) -> 1 | X127: =IF(AND(W127=1,Q127<=Settings!$B$36),1,0) -> 1
A128: 2 | B128: 3 | C128: =Arrivals!F128 -> 247.47628 | D128: =Arrivals!K128 -> 300 | E128: =D128*8/Settings!$B$28+Settings!$B$29 -> 24.02 | F128: =C128 -> 247.47628 | G128: =K127 -> 179.25131 | H128: =MAX(F128,G128) -> 247.47628 | I128: =MOD(H128-Settings!$B$32,Settings!$B$33) -> 247.47628 | J128: =IF(I128<Settings!$B$30,IF(Settings!$B$30-I128>=E128,H128,H128+(Settings!$B$30-I128)+Settings!$B$31),H128+(Settings!$B$33-I128)) -> 247.47628 | K128: =J128+E128 -> 271.49628 | L128: =K128 -> 271.49628 | M128: =P127 -> 183.5693 | N128: =MAX(L128,M128) -> 271.49628 | O128: =Arrivals!I128 -> 3.2176439 | P128: =N128+O128 -> 274.71392 | Q128: =P128-C128 -> 27.237644 | R128: =H128-F128 -> 0 | S128: =J128-H128 -> 0 | T128: =N128-L128 -> 0 | U128: =R128+S128+T128 -> 0 | V128: =IF(MOD(C128-Settings!$B$32,Settings!$B$33)<Settings!$B$30,"Up","Down") -> Up | W128: =IF(OR(E128>Settings!$B$30,Q128>Settings!$B$37),0,1) -> 1 | X128: =IF(AND(W128=1,Q128<=Settings!$B$36),1,0) -> 1
A129: 2 | B129: 4 | C129: =Arrivals!F129 -> 312.88949 | D129: =Arrivals!K129 -> 300 | E129: =D129*8/Settings!$B$28+Settings!$B$29 -> 24.02 | F129: =C129 -> 312.88949 | G129: =K128 -> 271.49628 | H129: =MAX(F129,G129) -> 312.88949 | I129: =MOD(H129-Settings!$B$32,Settings!$B$33) -> 312.88949 | J129: =IF(I129<Settings!$B$30,IF(Settings!$B$30-I129>=E129,H129,H129+(Settings!$B$30-I129)+Settings!$B$31),H129+(Settings!$B$33-I129)) -> 312.88949 | K129: =J129+E129 -> 336.90949 | L129: =K129 -> 336.90949 | M129: =P128 -> 274.71392 | N129: =MAX(L129,M129) -> 336.90949 | O129: =Arrivals!I129 -> 1.8223202 | P129: =N129+O129 -> 338.73181 | Q129: =P129-C129 -> 25.84232 | R129: =H129-F129 -> 0 | S129: =J129-H129 -> 0 | T129: =N129-L129 -> 0 | U129: =R129+S129+T129 -> 0 | V129: =IF(MOD(C129-Settings!$B$32,Settings!$B$33)<Settings!$B$30,"Up","Down") -> Up | W129: =IF(OR(E129>Settings!$B$30,Q129>Settings!$B$37),0,1) -> 1 | X129: =IF(AND(W129=1,Q129<=Settings!$B$36),1,0) -> 1
A130: 2 | B130: 5 | C130: =Arrivals!F130 -> 349.1954 | D130: =Arrivals!K130 -> 300 | E130: =D130*8/Settings!$B$28+Settings!$B$29 -> 24.02 | F130: =C130 -> 349.1954 | G130: =K129 -> 336.90949 | H130: =MAX(F130,G130) -> 349.1954 | I130: =MOD(H130-Settings!$B$32,Settings!$B$33) -> 349.1954 | J130: =IF(I130<Settings!$B$30,IF(Settings!$B$30-I130>=E130,H130,H130+(Settings!$B$30-I130)+Settings!$B$31),H130+(Settings!$B$33-I130)) -> 349.1954 | K130: =J130+E130 -> 373.2154 | L130: =K130 -> 373.2154 | M130: =P129 -> 338.73181 | N130: =MAX(L130,M130) -> 373.2154 | O130: =Arrivals!I130 -> 0.06623216 | P130: =N130+O130 -> 373.28163 | Q130: =P130-C130 -> 24.086232 | R130: =H130-F130 -> 0 | S130: =J130-H130 -> 0 | T130: =N130-L130 -> 0 | U130: =R130+S130+T130 -> 0 | V130: =IF(MOD(C130-Settings!$B$32,Settings!$B$33)<Settings!$B$30,"Up","Down") -> Up | W130: =IF(OR(E130>Settings!$B$30,Q130>Settings!$B$37),0,1) -> 1 | X130: =IF(AND(W130=1,Q130<=Settings!$B$36),1,0) -> 1
A131: 2 | B131: 6 | C131: =Arrivals!F131 -> 351.05216 | D131: =Arrivals!K131 -> 300 | E131: =D131*8/Settings!$B$28+Settings!$B$29 -> 24.02 | F131: =C131 -> 351.05216 | G131: =K130 -> 373.2154 | H131: =MAX(F131,G131) -> 373.2154 | I131: =MOD(H131-Settings!$B$32,Settings!$B$33) -> 373.2154 | J131: =IF(I131<Settings!$B$30,IF(Settings!$B$30-I131>=E131,H131,H131+(Settings!$B$30-I131)+Settings!$B$31),H131+(Settings!$B$33-I131)) -> 373.2154 | K131: =J131+E131 -> 397.2354 | L131: =K131 -> 397.2354 | M131: =P130 -> 373.28163 | N131: =MAX(L131,M131) -> 397.2354 | O131: =Arrivals!I131 -> 32.027258 | P131: =N131+O131 -> 429.26266 | Q131: =P131-C131 -> 78.210495 | R131: =H131-F131 -> 22.163237 | S131: =J131-H131 -> 0 | T131: =N131-L131 -> 0 | U131: =R131+S131+T131 -> 22.163237 | V131: =IF(MOD(C131-Settings!$B$32,Settings!$B$33)<Settings!$B$30,"Up","Down") -> Up | W131: =IF(OR(E131>Settings!$B$30,Q131>Settings!$B$37),0,1) -> 1 | X131: =IF(AND(W131=1,Q131<=Settings!$B$36),1,0) -> 1
A132: 2 | B132: 7 | C132: =Arrivals!F132 -> 360.45001 | D132: =Arrivals!K132 -> 300 | E132: =D132*8/Settings!$B$28+Settings!$B$29 -> 24.02 | F132: =C132 -> 360.45001 | G132: =K131 -> 397.2354 | H132: =MAX(F132,G132) -> 397.2354 | I132: =MOD(H132-Settings!$B$32,Settings!$B$33) -> 397.2354 | J132: =IF(I132<Settings!$B$30,IF(Settings!$B$30-I132>=E132,H132,H132+(Settings!$B$30-I132)+Settings!$B$31),H132+(Settings!$B$33-I132)) -> 397.2354 | K132: =J132+E132 -> 421.2554 | L132: =K132 -> 421.2554 | M132: =P131 -> 429.26266 | N132: =MAX(L132,M132) -> 429.26266 | O132: =Arrivals!I132 -> 2.0444372 | P132: =N132+O132 -> 431.30709 | Q132: =P132-C132 -> 70.857079 | R132: =H132-F132 -> 36.785384 | S132: =J132-H132 -> 0 | T132: =N132-L132 -> 8.0072582 | U132: =R132+S132+T132 -> 44.792642 | V132: =IF(MOD(C132-Settings!$B$32,Settings!$B$33)<Settings!$B$30,"Up","Down") -> Up | W132: =IF(OR(E132>Settings!$B$30,Q132>Settings!$B$37),0,1) -> 1 | X132: =IF(AND(W132=1,Q132<=Settings!$B$36),1,0) -> 1
A133: 2 | B133: 8 | C133: =Arrivals!F133 -> 429.88234 | D133: =Arrivals!K133 -> 300 | E133: =D133*8/Settings!$B$28+Settings!$B$29 -> 24.02 | F133: =C133 -> 429.88234 | G133: =K132 -> 421.2554 | H133: =MAX(F133,G133) -> 429.88234 | I133: =MOD(H133-Settings!$B$32,Settings!$B$33) -> 429.88234 | J133: =IF(I133<Settings!$B$30,IF(Settings!$B$30-I133>=E133,H133,H133+(Settings!$B$30-I133)+Settings!$B$31),H133+(Settings!$B$33-I133)) -> 429.88234 | K133: =J133+E133 -> 453.90234 | L133: =K133 -> 453.90234 | M133: =P132 -> 431.30709 | N133: =MAX(L133,M133) -> 453.90234 | O133: =Arrivals!I133 -> 4.3185489 | P133: =N133+O133 -> 458.22089 | Q133: =P133-C133 -> 28.338549 | R133: =H133-F133 -> 0 | S133: =J133-H133 -> 0 | T133: =N133-L133 -> 0 | U133: =R133+S133+T133 -> 0 | V133: =IF(MOD(C133-Settings!$B$32,Settings!$B$33)<Settings!$B$30,"Up","Down") -> Up | W133: =IF(OR(E133>Settings!$B$30,Q133>Settings!$B$37),0,1) -> 1 | X133: =IF(AND(W133=1,Q133<=Settings!$B$36),1,0) -> 1
A134: 2 | B134: 9 | C134: =Arrivals!F134 -> 470.64389 | D134: =Arrivals!K134 -> 300 | E134: =D134*8/Settings!$B$28+Settings!$B$29 -> 24.02 | F134: =C134 -> 470.64389 | G134: =K133 -> 453.90234 | H134: =MAX(F134,G134) -> 470.64389 | I134: =MOD(H134-Settings!$B$32,Settings!$B$33) -> 470.64389 | J134: =IF(I134<Settings!$B$30,IF(Settings!$B$30-I134>=E134,H134,H134+(Settings!$B$30-I134)+Settings!$B$31),H134+(Settings!$B$33-I134)) -> 470.64389 | K134: =J134+E134 -> 494.66389 | L134: =K134 -> 494.66389 | M134: =P133 -> 458.22089 | N134: =MAX(L134,M134) -> 494.66389 | O134: =Arrivals!I134 -> 1.7054899 | P134: =N134+O134 -> 496.36938 | Q134: =P134-C134 -> 25.72549 | R134: =H134-F134 -> 0 | S134: =J134-H134 -> 0 | T134: =N134-L134 -> 0 | U134: =R134+S134+T134 -> 0 | V134: =IF(MOD(C134-Settings!$B$32,Settings!$B$33)<Settings!$B$30,"Up","Down") -> Up | W134: =IF(OR(E134>Settings!$B$30,Q134>Settings!$B$37),0,1) -> 1 | X134: =IF(AND(W134=1,Q134<=Settings!$B$36),1,0) -> 1
A135: 2 | B135: 10 | C135: =Arrivals!F135 -> 577.10538 | D135: =Arrivals!K135 -> 300 | E135: =D135*8/Settings!$B$28+Settings!$B$29 -> 24.02 | F135: =C135 -> 577.10538 | G135: =K134 -> 494.66389 | H135: =MAX(F135,G135) -> 577.10538 | I135: =MOD(H135-Settings!$B$32,Settings!$B$33) -> 577.10538 | J135: =IF(I135<Settings!$B$30,IF(Settings!$B$30-I135>=E135,H135,H135+(Settings!$B$30-I135)+Settings!$B$31),H135+(Settings!$B$33-I135)) -> 720 | K135: =J135+E135 -> 744.02 | L135: =K135 -> 744.02 | M135: =P134 -> 496.36938 | N135: =MAX(L135,M135) -> 744.02 | O135: =Arrivals!I135 -> 0.70412258 | P135: =N135+O135 -> 744.72412 | Q135: =P135-C135 -> 167.61874 | R135: =H135-F135 -> 0 | S135: =J135-H135 -> 142.89462 | T135: =N135-L135 -> 0 | U135: =R135+S135+T135 -> 142.89462 | V135: =IF(MOD(C135-Settings!$B$32,Settings!$B$33)<Settings!$B$30,"Up","Down") -> Up | W135: =IF(OR(E135>Settings!$B$30,Q135>Settings!$B$37),0,1) -> 1 | X135: =IF(AND(W135=1,Q135<=Settings!$B$36),1,0) -> 0
A136: 2 | B136: 11 | C136: =Arrivals!F136 -> 642.31205 | D136: =Arrivals!K136 -> 300 | E136: =D136*8/Settings!$B$28+Settings!$B$29 -> 24.02 | F136: =C136 -> 642.31205 | G136: =K135 -> 744.02 | H136: =MAX(F136,G136) -> 744.02 | I136: =MOD(H136-Settings!$B$32,Settings!$B$33) -> 24.02 | J136: =IF(I136<Settings!$B$30,IF(Settings!$B$30-I136>=E136,H136,H136+(Settings!$B$30-I136)+Settings!$B$31),H136+(Settings!$B$33-I136)) -> 744.02 | K136: =J136+E136 -> 768.04 | L136: =K136 -> 768.04 | M136: =P135 -> 744.72412 | N136: =MAX(L136,M136) -> 768.04 | O136: =Arrivals!I136 -> 6.0473159 | P136: =N136+O136 -> 774.08732 | Q136: =P136-C136 -> 131.77527 | R136: =H136-F136 -> 101.70795 | S136: =J136-H136 -> 0 | T136: =N136-L136 -> 0 | U136: =R136+S136+T136 -> 101.70795 | V136: =IF(MOD(C136-Settings!$B$32,Settings!$B$33)<Settings!$B$30,"Up","Down") -> Down | W136: =IF(OR(E136>Settings!$B$30,Q136>Settings!$B$37),0,1) -> 1 | X136: =IF(AND(W136=1,Q136<=Settings!$B$36),1,0) -> 0
A137: 2 | B137: 12 | C137: =Arrivals!F137 -> 857.15163 | D137: =Arrivals!K137 -> 300 | E137: =D137*8/Settings!$B$28+Settings!$B$29 -> 24.02 | F137: =C137 -> 857.15163 | G137: =K136 -> 768.04 | H137: =MAX(F137,G137) -> 857.15163 | I137: =MOD(H137-Settings!$B$32,Settings!$B$33) -> 137.15163 | J137: =IF(I137<Settings!$B$30,IF(Settings!$B$30-I137>=E137,H137,H137+(Settings!$B$30-I137)+Settings!$B$31),H137+(Settings!$B$33-I137)) -> 857.15163 | K137: =J137+E137 -> 881.17163 | L137: =K137 -> 881.17163 | M137: =P136 -> 774.08732 | N137: =MAX(L137,M137) -> 881.17163 | O137: =Arrivals!I137 -> 12.023838 | P137: =N137+O137 -> 893.19547 | Q137: =P137-C137 -> 36.043838 | R137: =H137-F137 -> 0 | S137: =J137-H137 -> 0 | T137: =N137-L137 -> 0 | U137: =R137+S137+T137 -> 0 | V137: =IF(MOD(C137-Settings!$B$32,Settings!$B$33)<Settings!$B$30,"Up","Down") -> Up | W137: =IF(OR(E137>Settings!$B$30,Q137>Settings!$B$37),0,1) -> 1 | X137: =IF(AND(W137=1,Q137<=Settings!$B$36),1,0) -> 1
A138: 2 | B138: 13 | C138: =Arrivals!F138 -> 954.35427 | D138: =Arrivals!K138 -> 300 | E138: =D138*8/Settings!$B$28+Settings!$B$29 -> 24.02 | F138: =C138 -> 954.35427 | G138: =K137 -> 881.17163 | H138: =MAX(F138,G138) -> 954.35427 | I138: =MOD(H138-Settings!$B$32,Settings!$B$33) -> 234.35427 | J138: =IF(I138<Settings!$B$30,IF(Settings!$B$30-I138>=E138,H138,H138+(Settings!$B$30-I138)+Settings!$B$31),H138+(Settings!$B$33-I138)) -> 954.35427 | K138: =J138+E138 -> 978.37427 | L138: =K138 -> 978.37427 | M138: =P137 -> 893.19547 | N138: =MAX(L138,M138) -> 978.37427 | O138: =Arrivals!I138 -> 0.89628395 | P138: =N138+O138 -> 979.27056 | Q138: =P138-C138 -> 24.916284 | R138: =H138-F138 -> 0 | S138: =J138-H138 -> 0 | T138: =N138-L138 -> 0 | U138: =R138+S138+T138 -> 0 | V138: =IF(MOD(C138-Settings!$B$32,Settings!$B$33)<Settings!$B$30,"Up","Down") -> Up | W138: =IF(OR(E138>Settings!$B$30,Q138>Settings!$B$37),0,1) -> 1 | X138: =IF(AND(W138=1,Q138<=Settings!$B$36),1,0) -> 1
... A245: 2 | B245: 120 | C245: =Arrivals!F245 -> 7157.0812 | D245: =Arrivals!K245 -> 300 | E245: =D245*8/Settings!$B$28+Settings!$B$29 -> 24.02 | F245: =C245 -> 7157.0812 | G245: =K244 -> 7296.08 | H245: =MAX(F245,G245) -> 7296.08 | I245: =MOD(H245-Settings!$B$32,Settings!$B$33) -> 96.08 | J245: =IF(I245<Settings!$B$30,IF(Settings!$B$30-I245>=E245,H245,H245+(Settings!$B$30-I245)+Settings!$B$31),H245+(Settings!$B$33-I245)) -> 7296.08 | K245: =J245+E245 -> 7320.1 | L245: =K245 -> 7320.1 | M245: =P244 -> 7302.9372 | N245: =MAX(L245,M245) -> 7320.1 | O245: =Arrivals!I245 -> 0.92361396 | P245: =N245+O245 -> 7321.0236 | Q245: =P245-C245 -> 163.94241 | R245: =H245-F245 -> 138.9988 | S245: =J245-H245 -> 0 | T245: =N245-L245 -> 0 | U245: =R245+S245+T245 -> 138.9988 | V245: =IF(MOD(C245-Settings!$B$32,Settings!$B$33)<Settings!$B$30,"Up","Down") -> Down | W245: =IF(OR(E245>Settings!$B$30,Q245>Settings!$B$37),0,1) -> 1 | X245: =IF(AND(W245=1,Q245<=Settings!$B$36),1,0) -> 0
A246: 3 | B246: 1 | C246: =Arrivals!F246 -> 127.16801 | D246: =Arrivals!K246 -> 300 | E246: =D246*8/Settings!$B$28+Settings!$B$29 -> 24.02 | F246: =C246 -> 127.16801 | G246: 0 | H246: =MAX(F246,G246) -> 127.16801 | I246: =MOD(H246-Settings!$B$32,Settings!$B$33) -> 127.16801 | J246: =IF(I246<Settings!$B$30,IF(Settings!$B$30-I246>=E246,H246,H246+(Settings!$B$30-I246)+Settings!$B$31),H246+(Settings!$B$33-I246)) -> 127.16801 | K246: =J246+E246 -> 151.18801 | L246: =K246 -> 151.18801 | M246: 0 | N246: =MAX(L246,M246) -> 151.18801 | O246: =Arrivals!I246 -> 3.2063581 | P246: =N246+O246 -> 154.39437 | Q246: =P246-C246 -> 27.226358 | R246: =H246-F246 -> 0 | S246: =J246-H246 -> 0 | T246: =N246-L246 -> 0 | U246: =R246+S246+T246 -> 0 | V246: =IF(MOD(C246-Settings!$B$32,Settings!$B$33)<Settings!$B$30,"Up","Down") -> Up | W246: =IF(OR(E246>Settings!$B$30,Q246>Settings!$B$37),0,1) -> 1 | X246: =IF(AND(W246=1,Q246<=Settings!$B$36),1,0) -> 1
A247: 3 | B247: 2 | C247: =Arrivals!F247 -> 175.43164 | D247: =Arrivals!K247 -> 300 | E247: =D247*8/Settings!$B$28+Settings!$B$29 -> 24.02 | F247: =C247 -> 175.43164 | G247: =K246 -> 151.18801 | H247: =MAX(F247,G247) -> 175.43164 | I247: =MOD(H247-Settings!$B$32,Settings!$B$33) -> 175.43164 | J247: =IF(I247<Settings!$B$30,IF(Settings!$B$30-I247>=E247,H247,H247+(Settings!$B$30-I247)+Settings!$B$31),H247+(Settings!$B$33-I247)) -> 175.43164 | K247: =J247+E247 -> 199.45164 | L247: =K247 -> 199.45164 | M247: =P246 -> 154.39437 | N247: =MAX(L247,M247) -> 199.45164 | O247: =Arrivals!I247 -> 0.52246644 | P247: =N247+O247 -> 199.9741 | Q247: =P247-C247 -> 24.542466 | R247: =H247-F247 -> 0 | S247: =J247-H247 -> 0 | T247: =N247-L247 -> 0 | U247: =R247+S247+T247 -> 0 | V247: =IF(MOD(C247-Settings!$B$32,Settings!$B$33)<Settings!$B$30,"Up","Down") -> Up | W247: =IF(OR(E247>Settings!$B$30,Q247>Settings!$B$37),0,1) -> 1 | X247: =IF(AND(W247=1,Q247<=Settings!$B$36),1,0) -> 1
A248: 3 | B248: 3 | C248: =Arrivals!F248 -> 191.60888 | D248: =Arrivals!K248 -> 300 | E248: =D248*8/Settings!$B$28+Settings!$B$29 -> 24.02 | F248: =C248 -> 191.60888 | G248: =K247 -> 199.45164 | H248: =MAX(F248,G248) -> 199.45164 | I248: =MOD(H248-Settings!$B$32,Settings!$B$33) -> 199.45164 | J248: =IF(I248<Settings!$B$30,IF(Settings!$B$30-I248>=E248,H248,H248+(Settings!$B$30-I248)+Settings!$B$31),H248+(Settings!$B$33-I248)) -> 199.45164 | K248: =J248+E248 -> 223.47164 | L248: =K248 -> 223.47164 | M248: =P247 -> 199.9741 | N248: =MAX(L248,M248) -> 223.47164 | O248: =Arrivals!I248 -> 11.774568 | P248: =N248+O248 -> 235.24621 | Q248: =P248-C248 -> 43.637325 | R248: =H248-F248 -> 7.8427567 | S248: =J248-H248 -> 0 | T248: =N248-L248 -> 0 | U248: =R248+S248+T248 -> 7.8427567 | V248: =IF(MOD(C248-Settings!$B$32,Settings!$B$33)<Settings!$B$30,"Up","Down") -> Up | W248: =IF(OR(E248>Settings!$B$30,Q248>Settings!$B$37),0,1) -> 1 | X248: =IF(AND(W248=1,Q248<=Settings!$B$36),1,0) -> 1
A249: 3 | B249: 4 | C249: =Arrivals!F249 -> 192.43812 | D249: =Arrivals!K249 -> 300 | E249: =D249*8/Settings!$B$28+Settings!$B$29 -> 24.02 | F249: =C249 -> 192.43812 | G249: =K248 -> 223.47164 | H249: =MAX(F249,G249) -> 223.47164 | I249: =MOD(H249-Settings!$B$32,Settings!$B$33) -> 223.47164 | J249: =IF(I249<Settings!$B$30,IF(Settings!$B$30-I249>=E249,H249,H249+(Settings!$B$30-I249)+Settings!$B$31),H249+(Settings!$B$33-I249)) -> 223.47164 | K249: =J249+E249 -> 247.49164 | L249: =K249 -> 247.49164 | M249: =P248 -> 235.24621 | N249: =MAX(L249,M249) -> 247.49164 | O249: =Arrivals!I249 -> 5.0321396 | P249: =N249+O249 -> 252.52378 | Q249: =P249-C249 -> 60.085654 | R249: =H249-F249 -> 31.033515 | S249: =J249-H249 -> 0 | T249: =N249-L249 -> 0 | U249: =R249+S249+T249 -> 31.033515 | V249: =IF(MOD(C249-Settings!$B$32,Settings!$B$33)<Settings!$B$30,"Up","Down") -> Up | W249: =IF(OR(E249>Settings!$B$30,Q249>Settings!$B$37),0,1) -> 1 | X249: =IF(AND(W249=1,Q249<=Settings!$B$36),1,0) -> 1
A250: 3 | B250: 5 | C250: =Arrivals!F250 -> 262.08179 | D250: =Arrivals!K250 -> 300 | E250: =D250*8/Settings!$B$28+Settings!$B$29 -> 24.02 | F250: =C250 -> 262.08179 | G250: =K249 -> 247.49164 | H250: =MAX(F250,G250) -> 262.08179 | I250: =MOD(H250-Settings!$B$32,Settings!$B$33) -> 262.08179 | J250: =IF(I250<Settings!$B$30,IF(Settings!$B$30-I250>=E250,H250,H250+(Settings!$B$30-I250)+Settings!$B$31),H250+(Settings!$B$33-I250)) -> 262.08179 | K250: =J250+E250 -> 286.10179 | L250: =K250 -> 286.10179 | M250: =P249 -> 252.52378 | N250: =MAX(L250,M250) -> 286.10179 | O250: =Arrivals!I250 -> 1.1463802 | P250: =N250+O250 -> 287.24818 | Q250: =P250-C250 -> 25.16638 | R250: =H250-F250 -> 0 | S250: =J250-H250 -> 0 | T250: =N250-L250 -> 0 | U250: =R250+S250+T250 -> 0 | V250: =IF(MOD(C250-Settings!$B$32,Settings!$B$33)<Settings!$B$30,"Up","Down") -> Up | W250: =IF(OR(E250>Settings!$B$30,Q250>Settings!$B$37),0,1) -> 1 | X250: =IF(AND(W250=1,Q250<=Settings!$B$36),1,0) -> 1
A251: 3 | B251: 6 | C251: =Arrivals!F251 -> 266.51905 | D251: =Arrivals!K251 -> 300 | E251: =D251*8/Settings!$B$28+Settings!$B$29 -> 24.02 | F251: =C251 -> 266.51905 | G251: =K250 -> 286.10179 | H251: =MAX(F251,G251) -> 286.10179 | I251: =MOD(H251-Settings!$B$32,Settings!$B$33) -> 286.10179 | J251: =IF(I251<Settings!$B$30,IF(Settings!$B$30-I251>=E251,H251,H251+(Settings!$B$30-I251)+Settings!$B$31),H251+(Settings!$B$33-I251)) -> 286.10179 | K251: =J251+E251 -> 310.12179 | L251: =K251 -> 310.12179 | M251: =P250 -> 287.24818 | N251: =MAX(L251,M251) -> 310.12179 | O251: =Arrivals!I251 -> 0.16529051 | P251: =N251+O251 -> 310.28709 | Q251: =P251-C251 -> 43.768037 | R251: =H251-F251 -> 19.582746 | S251: =J251-H251 -> 0 | T251: =N251-L251 -> 0 | U251: =R251+S251+T251 -> 19.582746 | V251: =IF(MOD(C251-Settings!$B$32,Settings!$B$33)<Settings!$B$30,"Up","Down") -> Up | W251: =IF(OR(E251>Settings!$B$30,Q251>Settings!$B$37),0,1) -> 1 | X251: =IF(AND(W251=1,Q251<=Settings!$B$36),1,0) -> 1
A252: 3 | B252: 7 | C252: =Arrivals!F252 -> 272.86496 | D252: =Arrivals!K252 -> 300 | E252: =D252*8/Settings!$B$28+Settings!$B$29 -> 24.02 | F252: =C252 -> 272.86496 | G252: =K251 -> 310.12179 | H252: =MAX(F252,G252) -> 310.12179 | I252: =MOD(H252-Settings!$B$32,Settings!$B$33) -> 310.12179 | J252: =IF(I252<Settings!$B$30,IF(Settings!$B$30-I252>=E252,H252,H252+(Settings!$B$30-I252)+Settings!$B$31),H252+(Settings!$B$33-I252)) -> 310.12179 | K252: =J252+E252 -> 334.14179 | L252: =K252 -> 334.14179 | M252: =P251 -> 310.28709 | N252: =MAX(L252,M252) -> 334.14179 | O252: =Arrivals!I252 -> 1.7574568 | P252: =N252+O252 -> 335.89925 | Q252: =P252-C252 -> 63.034288 | R252: =H252-F252 -> 37.256831 | S252: =J252-H252 -> 0 | T252: =N252-L252 -> 0 | U252: =R252+S252+T252 -> 37.256831 | V252: =IF(MOD(C252-Settings!$B$32,Settings!$B$33)<Settings!$B$30,"Up","Down") -> Up | W252: =IF(OR(E252>Settings!$B$30,Q252>Settings!$B$37),0,1) -> 1 | X252: =IF(AND(W252=1,Q252<=Settings!$B$36),1,0) -> 1
A253: 3 | B253: 8 | C253: =Arrivals!F253 -> 376.06021 | D253: =Arrivals!K253 -> 300 | E253: =D253*8/Settings!$B$28+Settings!$B$29 -> 24.02 | F253: =C253 -> 376.06021 | G253: =K252 -> 334.14179 | H253: =MAX(F253,G253) -> 376.06021 | I253: =MOD(H253-Settings!$B$32,Settings!$B$33) -> 376.06021 | J253: =IF(I253<Settings!$B$30,IF(Settings!$B$30-I253>=E253,H253,H253+(Settings!$B$30-I253)+Settings!$B$31),H253+(Settings!$B$33-I253)) -> 376.06021 | K253: =J253+E253 -> 400.08021 | L253: =K253 -> 400.08021 | M253: =P252 -> 335.89925 | N253: =MAX(L253,M253) -> 400.08021 | O253: =Arrivals!I253 -> 6.3500089 | P253: =N253+O253 -> 406.43022 | Q253: =P253-C253 -> 30.370009 | R253: =H253-F253 -> 0 | S253: =J253-H253 -> 0 | T253: =N253-L253 -> 0 | U253: =R253+S253+T253 -> 0 | V253: =IF(MOD(C253-Settings!$B$32,Settings!$B$33)<Settings!$B$30,"Up","Down") -> Up | W253: =IF(OR(E253>Settings!$B$30,Q253>Settings!$B$37),0,1) -> 1 | X253: =IF(AND(W253=1,Q253<=Settings!$B$36),1,0) -> 1
A254: 3 | B254: 9 | C254: =Arrivals!F254 -> 389.19828 | D254: =Arrivals!K254 -> 300 | E254: =D254*8/Settings!$B$28+Settings!$B$29 -> 24.02 | F254: =C254 -> 389.19828 | G254: =K253 -> 400.08021 | H254: =MAX(F254,G254) -> 400.08021 | I254: =MOD(H254-Settings!$B$32,Settings!$B$33) -> 400.08021 | J254: =IF(I254<Settings!$B$30,IF(Settings!$B$30-I254>=E254,H254,H254+(Settings!$B$30-I254)+Settings!$B$31),H254+(Settings!$B$33-I254)) -> 400.08021 | K254: =J254+E254 -> 424.10021 | L254: =K254 -> 424.10021 | M254: =P253 -> 406.43022 | N254: =MAX(L254,M254) -> 424.10021 | O254: =Arrivals!I254 -> 0.20821029 | P254: =N254+O254 -> 424.30842 | Q254: =P254-C254 -> 35.110141 | R254: =H254-F254 -> 10.88193 | S254: =J254-H254 -> 0 | T254: =N254-L254 -> 0 | U254: =R254+S254+T254 -> 10.88193 | V254: =IF(MOD(C254-Settings!$B$32,Settings!$B$33)<Settings!$B$30,"Up","Down") -> Up | W254: =IF(OR(E254>Settings!$B$30,Q254>Settings!$B$37),0,1) -> 1 | X254: =IF(AND(W254=1,Q254<=Settings!$B$36),1,0) -> 1
