Workbook

Sheet DASHBOARD
A1: OPS-SAT SIMULTANEOUS ACE | GROUND vs ORBITAL EDGE
A2: Carlo Antonio Nino · GWU D.Eng. Praxis · Simultaneous OPS-SAT ACE v02
A3: ACE DATA > NORMALIZE / FUSE > GROUND vs EDGE DES > RESULTS
A5: A · ACE INPUTS
A6: Leg | B6: Source | C6: Contribution | D6: Records in window | F6: Data class
A7: AI / ML | B7: OPSSAT-AD v2 onboard telemetry | C7: Arrival chronology, segment and anomaly context | D7: =Protocol!B10&" accepted" -> 100 accepted | E7: ="of "&Protocol!B11 -> of 111 | F7: OBSERVED
A8: COMM | B8: SatNOGS decoded OPS-SAT receptions | C8: Radio state, beacon activity, counter deltas | D8: =COUNTA(COMM_Decoded!$B$6:$B$105)&" admitted" -> 100 admitted | E8: ="of "&COUNTA(COMM_Receptions!$B$6:$B$106) -> of 101 | F8: OBSERVED state only
A9: ENV | B9: NASA OMNI near-Earth environment | C9: Space-environment context by UTC minute | D9: =COUNTA(OMNI_Normalized!$A$6:$A$18)&" in-window minutes" -> 13 in-window minutes | E9: ="of "&COUNTA(OMNI_Raw!$A$6:$A$125)&" rows" -> of 120 rows | F9: OBSERVED context only
A11: Spacecraft | B11: OPS-SAT, NORAD 44878 | C11: Common UTC window | D11: =Protocol!C7 -> 2022-01-28 17:42:49 UTC; integer seconds since 1970 | F11: =Protocol!C8 -> 2022-01-28 17:54:19 UTC; endpoints inclusive
A12: Window length (s) | B12: =Settings!B10 -> 690 | C12: Accepted / rejected observations | D12: =Protocol!B10&" accepted" -> 100 accepted | E12: =(Protocol!B11-Protocol!B10)&" rejected" -> 11 rejected | F12: =Protocol!B16 -> QUALIFIED PASS — STATE-DATA FIT
A13: Synchronization rule | B13: =Protocol!B14 -> Latest preceding validated-header beacon | C13: COMM tolerance (s) | D13: =Protocol!B9 -> 10 | E13: ENV join | F13: =Protocol!B15 -> UTC minute bin [minute,minute+60 s)
A14: Fused cohort | B14: =COUNTA(ACE_Input!$A$6:$A$105)&" observations" -> 100 observations | C14: Replications | D14: =Settings!B9 -> 10 | E14: Paired entities | F14: =COUNTA(ACE_Input!$A$6:$A$105)*Settings!B9 -> 1000
A16: NOT ESTABLISHED by these sources: link capacity, packet loss, propagation delay, outage duration. Co-timing is association with a stated tolerance, not causation.
A17: Prior A, C and E data-fit runs are retained on their own sheets for lineage. They are from different periods and are not inputs to this synchronized run.
A19: B · ENV / COMM SNAPSHOT · representative synchronized record (entity 1 of the cohort)
A20: UTC | B20: SOURCE | C20: VARIABLE | D20: VALUE | E20: UNIT | F20: DATA CLASS
A21: =ACE_Input!C6 -> 44589.738 | B21: OPSSAT-AD | C21: ="Telemetry value, channel "&ACE_Input!G6 -> Telemetry value, channel CADC0873 | D21: =ACE_Input!H6 -> 0 | E21: source units | F21: OBSERVED
A22: =ACE_Input!C6 -> 44589.738 | B22: OPSSAT-AD | C22: Anomaly label | D22: =ACE_Input!F6 -> 1 | E22: flag | F22: OBSERVED
A23: =ACE_Input!C6 -> 44589.738 | B23: OPSSAT-AD | C23: Segment | D23: =ACE_Input!E6 -> 1352 | E23: id | F23: OBSERVED
A24: =ACE_Input!I6 -> 44589.738 | B24: SatNOGS | C24: Latest preceding validated beacon | D24: =ACE_Input!K6 -> 203 | E24: JSON row | F24: OBSERVED
A25: =ACE_Input!I6 -> 44589.738 | B25: SatNOGS | C25: COMM association age | D25: =ACE_Input!J6 -> 2 | E25: s | F25: DERIVED / PROXY
A26: =ACE_Input!L6 -> 44589.738 | B26: NASA OMNI | C26: Magnetic field average | D26: =ACE_Input!M6 -> 6.41 | E26: nT | F26: OBSERVED
A27: =ACE_Input!L6 -> 44589.738 | B27: NASA OMNI | C27: Bz GSM | D27: =ACE_Input!N6 -> -1.15 | E27: nT | F27: OBSERVED
A28: =ACE_Input!L6 -> 44589.738 | B28: NASA OMNI | C28: Solar wind speed | D28: =ACE_Input!O6 -> 419.9 | E28: km/s | F28: OBSERVED
A29: =ACE_Input!L6 -> 44589.738 | B29: NASA OMNI | C29: AE index | D29: =ACE_Input!Q6 -> 96 | E29: nT | F29: OBSERVED
A30: =ACE_Input!L6 -> 44589.738 | B30: NASA OMNI | C30: SYM/H index | D30: =ACE_Input!R6 -> 1 | E30: nT | F30: OBSERVED
A31: model input | B31: DES assumption | C31: Link rate | D31: =ACE_Input!S6 -> 100 | E31: Mbps | F31: SYNTHETIC
A32: model input | B32: DES assumption | C32: Raw observation volume | D32: =ACE_Input!U6 -> 300 | E32: MB | F32: SYNTHETIC
A33: model input | B33: DES assumption | C33: Edge output fraction | D33: =ACE_Input!V6 -> 0.25 | E33: share | F33: SYNTHETIC
A35: No environmental value is converted into a communications outage or degradation anywhere in this model. Association is by UTC only.
A37: C · SCENARIO CONTROLS
A38: Control | B38: Value | C38: Control | D38: Value | F38: Data class
A39: Architectures compared | B39: Ground-centric vs bounded orbital edge | C39: Entities per replication | D39: =Settings!B8 -> 100 | F39: CONTROLLED
A40: Observation volume (MB) | B40: =Settings!B12 -> 300 | C40: Replications | D40: =Settings!B9 -> 10 | F40: SYNTHETIC / CONTROLLED
A41: Edge output fraction | B41: =Settings!B25 -> 0.25 | C41: Ground processing mean (s) | D41: =Settings!B21 -> 4 | F41: SYNTHETIC
A42: Link rate (Mbps) | B42: =Settings!B28 -> 100 | C42: Onboard processing mean (s) | D42: =Settings!B24 -> 12 | F42: SYNTHETIC
A43: Link up window (s) | B43: =Settings!B30 -> 600 | C43: Propagation delay (s) | D43: =Settings!B29 -> 0.02 | F43: SYNTHETIC
A44: Link down window (s) | B44: =Settings!B31 -> 120 | C44: Link availability (share) | D44: =Comparison!B41 -> 0.86956522 | F44: SYNTHETIC
A45: Service deadline (s) | B45: =Settings!B36 -> 120 | C45: Staleness threshold (s) | D45: =Settings!B37 -> 900 | F45: CONTROLLED
A46: Processing seed base | B46: =Settings!B16 -> 54321 | C46: Seed rule | D46: ="seed + 1000 x replication" -> seed + 1000 x replication | F46: CONTROLLED
...

Sheet INTRO
A1: OPS-SAT | SIMULTANEOUS ACE v02
A3: Carlo Antonio Nino · GWU D.Eng. Praxis · 23 September 2026 Window: 28 January 2022, 17:42:49–17:54:19 UTC
A6: QUALIFIED PASS Synchronized radio-state data fit | E6: NOT CALIBRATED Rate, delay and outages remain synthetic
A9: RECEPTIONS REVIEWED | C9: DECODED ADMISSIONS | E9: DISTINCT BEACONS | G9: ACE OBSERVATIONS
A10: =COMM_Decode_QC!B6 -> 101 | C10: =COMM_Decode_QC!B7 -> 100 | E10: =COMM_Decode_QC!B9 -> 61 | G10: =COMM_Decode_QC!B29 -> 100
A13: 65/65 retained CRC32-C checks pass. One malformed AX.25 source header is rejected, not repaired. The 61-beacon series contains 54 CRC-verified and 7 preprocessed-only beacons; 10 of the 100 ACE observations use a no-CRC witness.
A17: WHAT CHANGED: 18 decoded radio fields and counter-activity attributes now accompany the same AI/ML–COMM–ENV timeline. TX counters advance by 69 packets and 6,486 bytes across 690 s; 9.4 B/s is radio activity, NOT available link capacity.
A21: GROUND / EDGE RESULTS | assumption-conditioned simulation
A22: Scenario | C22: Ground mean, s | E22: Edge mean, s | G22: Lower modeled time
A23: Inherited 300 MB | C23: =Sensitivity!G6 -> 1067.8567 | E23: =Sensitivity!H6 -> 280.18075 | G23: =IF(ABS(C23-E23)<0.000001,"TIE",IF(C23<E23,"GROUND","EDGE")) -> EDGE
A24: 1 MB workload | C24: =Sensitivity!G7 -> 16.175254 | E24: =Sensitivity!H7 -> 262.43538 | G24: =IF(ABS(C24-E24)<0.000001,"TIE",IF(C24<E24,"GROUND","EDGE")) -> GROUND
A25: No volume reduction | C25: =Sensitivity!G8 -> 1067.8567 | E25: =Sensitivity!H8 -> 1072.3114 | G25: =IF(ABS(C25-E25)<0.000001,"TIE",IF(C25<E25,"GROUND","EDGE")) -> GROUND
A26: 60 s edge compute | C26: =Sensitivity!G9 -> 1067.8567 | E26: =Sensitivity!H9 -> 2396.343 | G26: =IF(ABS(C26-E26)<0.000001,"TIE",IF(C26<E26,"GROUND","EDGE")) -> GROUND
A27: Identical paths | C27: =Sensitivity!G10 -> 1064.132 | E27: =Sensitivity!H10 -> 1064.132 | G27: =IF(ABS(C27-E27)<0.000001,"TIE",IF(C27<E27,"GROUND","EDGE")) -> TIE
A29: Results are unchanged: the same 100 arrivals and performance assumptions are used. 100 Mbps, 300 MB, 4/12 s compute, 25% output and the 600/120 s link cycle remain synthetic. Stale jobs are flagged after modeled completion, not cancelled from queues.
A33: OBSERVED RADIO STATE | onboard background RSSI Context only: no RSSI-to-throughput or RSSI-to-outage rule is imposed.
A52: QC SENSITIVITY: the qualified primary cohort remains 100 observations. Restricting all witnesses to CRC-verified beacons retains 90 at the same 10 s freshness rule. This is a distinct cohort option, not another independent dataset.
A56: METHOD: schema-driven Python adapter reads the uploaded opssat1.ksy and executes its unchanged SatNOGS descrambler. A second scalar reader cross-checks 1,800 values. Kaitai compiler and MATLAB were not executed. CRC checks do not establish spacecraft-to-ground timing calibration.
A61: START HERE: COMM_Decode_QC → COMM_Field_Map → COMM_Beacons → Join_Audit → ACE_Input → Settings / run sheets → Validation → Handoff. Raw originals and v01 are preserved.

Sheet Settings
A1: Settings - every input lives here
A2: Excel DES Baseline v1.2 | 19 September 2026 | Prepared by Carlo Antonio Nino, GWU D.Eng. Praxis
A3: PARTIAL-FIT DIAGNOSTIC. Real chronology + context; active performance assumptions remain synthetic. Not an empirical architecture finding.
A5: Blue cells on a yellow fill are inputs. Black cells are calculated. Change nothing else.
A7: SCENARIO
A8: Entities per replication | B8: =COUNTA(ACE_Input!A6:A105) -> 100 | C8: DERIVED / CONTROLLED. 100 accepted source observations. Cohort changes require a new configuration.
A9: Replications | B9: =Protocol!B12 -> 10 | C9: CONTROLLED. Ten conditional service replications of ONE observed trace, not ten independent passes.
A10: Scheduled assessment window (s) | B10: =Protocol!B8-Protocol!B7 -> 690 | C10: DERIVED. Bounded source window only; modeled completion may occur later under a synthetic schedule.
A11: Mean time between arrivals (s) | B11: 60 | C11: INACTIVE. Arrivals now replay measured telemetry times; this synthetic exponential mean is not used.
A12: Observation size (MB) | B12: 300 | C12: SYNTHETIC. Inherited 300 MB per modeled observation. Not measured OPS-SAT task bytes.
A14: RANDOM STREAMS
A15: Base seed, arrival stream | B15: 12345 | C15: INACTIVE arrival RNG retained for historical traceability.
A16: Base seed, processing stream | B16: 54321 | C16: ACTIVE synthetic service RNG. Same U for Ground and Edge, seed increment 1000 per rep.
A17: Generator multiplier a | B17: 16807 | C17: Park-Miller generator, as used in HW5.
A18: Generator modulus m | B18: 2147483647 | C18: 2^31 - 1.
A20: GROUND-CENTRIC PATH
A21: Ground processing mean time (s) | B21: 4 | C21: SYNTHETIC. Not OPSSAT-AD inference timing.
A23: ORBITAL EDGE PATH
A24: Onboard processing mean time (s) | B24: 12 | C24: SYNTHETIC. Paired service draw, larger assumed mean.
A25: Output fraction after filtering | B25: 0.25 | C25: SYNTHETIC. No measured before/after byte reduction is supplied.
A27: COMMUNICATIONS LINK (identical for both paths)
A28: Link rate (Mbps) | B28: 100 | C28: SYNTHETIC. Not throughput measured by SatNOGS and not calibrated to the OPS-SAT UHF radio.
A29: One-way propagation delay (s) | B29: 0.02 | C29: SYNTHETIC. Not a measured one-way delay.
A30: Link up window (s) | B30: 600 | C30: SYNTHETIC. Repeating availability scenario, not reception-derived uptime.
A31: Link down window (s) | B31: 120 | C31: SYNTHETIC. Not a historical outage; receptions may exist during this imposed scenario interval.
A32: Cycle offset (s) | B32: 0 | C32: SYNTHETIC. Counterfactual schedule anchored to the replay origin.
A33: Cycle length (s) | B33: =B30+B31 -> 720 | C33: Up window plus down window.
A35: ANALYSIS
A36: Service deadline (s) | B36: 120 | C36: Delivered later than this counts as outside the service deadline. Drives the availability measure.
A37: Staleness limit (s) | B37: 900 | C37: Not delivered by this time counts as dropped, not delivered. Keep it above the deadline.
A38: Significance level alpha | B38: 0.05 | C38: Two-sided. 0.05 with 9 degrees of freedom gives t = 2.2622, as in HW10.
A39: Acceptable-loss margin, availability | B39: 0.02 | C39: Recorded before testing. For a preservation claim only, never for an improvement claim.
A40: Main latency statistic, selected before testing | B40: Mean | C40: Type Mean, Median or P90. This choice drives the comparison sheet.
A42: HYPOTHESIS TEXT (editable, nothing is locked into the sheet)
A43: H0 latency (NULL HYPOTHESIS) | B43: Edge processing does not reduce the selected latency measure.
A44: H1 latency | B44: Edge processing reduces the selected latency measure.
A45: H0 availability (NULL HYPOTHESIS) | B45: Edge availability is not higher than ground availability.
A46: H1 availability | B46: Edge availability is higher than ground availability.
A48: Cohort is fixed by ACE_Input (100). To change the tolerance, entity set or replication design, regenerate and version the experiment. Performance assumptions remain editable.

Sheet Arrivals
A1: Arrivals - shared random streams used by BOTH paths
A2: 100 retained observation times replayed in each conditional replication. C:D are inactive historical arrival RNG diagnostics. G:J drive synthetic service demands.
A5: Rep | B5: Entity | C5: X arrival | D5: U arrival | E5: Interarrival (s) | F5: Arrival time (s) | G5: X service | H5: U service | I5: Ground proc time (s) | J5: Edge proc time (s) | K5: Ground volume (MB) | L5: Edge volume (MB)
A6: =1 -> 1 | B6: =ACE_Input!A6 -> 1 | C6: =MOD(Settings!$B$17*(Settings!$B$15+1000*A6),Settings!$B$18) -> 224289415 | D6: =MAX(C6,1)/Settings!$B$18 -> 0.1044429 | E6: =F6 -> 2 | F6: =ACE_Input!D6 -> 2 | G6: =MOD(Settings!$B$17*(Settings!$B$16+1000*A6),Settings!$B$18) -> 929780047 | H6: =MAX(G6,1)/Settings!$B$18 -> 0.43296257 | I6: =-ACE_Input!W6*LN(H6) -> 3.348416 | J6: =-ACE_Input!X6*LN(H6) -> 10.045248 | K6: =ACE_Input!U6 -> 300 | L6: =K6*ACE_Input!V6 -> 75
A7: =1 -> 1 | B7: =ACE_Input!A7 -> 2 | C7: =MOD(Settings!$B$17*(C6),Settings!$B$18) -> 798397420 | D7: =MAX(C7,1)/Settings!$B$18 -> 0.37178277 | E7: =F7-F6 -> 5 | F7: =ACE_Input!D7 -> 7 | G7: =MOD(Settings!$B$17*(G6),Settings!$B$18) -> 1722234357 | H7: =MAX(G7,1)/Settings!$B$18 -> 0.80197787 | I7: =-ACE_Input!W7*LN(H7) -> 0.88269707 | J7: =-ACE_Input!X7*LN(H7) -> 2.6480912 | K7: =ACE_Input!U7 -> 300 | L7: =K7*ACE_Input!V7 -> 75
A8: =1 -> 1 | B8: =ACE_Input!A8 -> 3 | C8: =MOD(Settings!$B$17*(C7),Settings!$B$18) -> 1187611484 | D8: =MAX(C8,1)/Settings!$B$18 -> 0.55302469 | E8: =F8-F7 -> 25 | F8: =ACE_Input!D8 -> 32 | G8: =MOD(Settings!$B$17*(G7),Settings!$B$18) -> 1808243833 | H8: =MAX(G8,1)/Settings!$B$18 -> 0.84202915 | I8: =-ACE_Input!W8*LN(H8) -> 0.68776257 | J8: =-ACE_Input!X8*LN(H8) -> 2.0632877 | K8: =ACE_Input!U8 -> 300 | L8: =K8*ACE_Input!V8 -> 75
A9: =1 -> 1 | B9: =ACE_Input!A9 -> 4 | C9: =MOD(Settings!$B$17*(C8),Settings!$B$18) -> 1473196370 | D9: =MAX(C9,1)/Settings!$B$18 -> 0.68601052 | E9: =F9-F8 -> 5 | F9: =ACE_Input!D9 -> 37 | G9: =MOD(Settings!$B$17*(G8),Settings!$B$18) -> 2113012534 | H9: =MAX(G9,1)/Settings!$B$18 -> 0.98394814 | I9: =-ACE_Input!W9*LN(H9) -> 0.064728358 | J9: =-ACE_Input!X9*LN(H9) -> 0.19418507 | K9: =ACE_Input!U9 -> 300 | L9: =K9*ACE_Input!V9 -> 75
A10: =1 -> 1 | B10: =ACE_Input!A10 -> 5 | C10: =MOD(Settings!$B$17*(C9),Settings!$B$18) -> 1672424327 | D10: =MAX(C10,1)/Settings!$B$18 -> 0.77878327 | E10: =F10-F9 -> 5 | F10: =ACE_Input!D10 -> 42 | G10: =MOD(Settings!$B$17*(G9),Settings!$B$18) -> 464588499 | H10: =MAX(G10,1)/Settings!$B$18 -> 0.21634088 | I10: =-ACE_Input!W10*LN(H10) -> 6.1235999 | J10: =-ACE_Input!X10*LN(H10) -> 18.3708 | K10: =ACE_Input!U10 -> 300 | L10: =K10*ACE_Input!V10 -> 75
A11: =1 -> 1 | B11: =ACE_Input!A11 -> 6 | C11: =MOD(Settings!$B$17*(C10),Settings!$B$18) -> 22208306 | D11: =MAX(C11,1)/Settings!$B$18 -> 0.010341548 | E11: =F11-F10 -> 5 | F11: =ACE_Input!D11 -> 47 | G11: =MOD(Settings!$B$17*(G10),Settings!$B$18) -> 88362201 | H11: =MAX(G11,1)/Settings!$B$18 -> 0.041146856 | I11: =-ACE_Input!W11*LN(H11) -> 12.762431 | J11: =-ACE_Input!X11*LN(H11) -> 38.287293 | K11: =ACE_Input!U11 -> 300 | L11: =K11*ACE_Input!V11 -> 75
A12: =1 -> 1 | B12: =ACE_Input!A12 -> 7 | C12: =MOD(Settings!$B$17*(C11),Settings!$B$18) -> 1740328011 | D12: =MAX(C12,1)/Settings!$B$18 -> 0.81040338 | E12: =F12-F11 -> 5 | F12: =ACE_Input!D12 -> 52 | G12: =MOD(Settings!$B$17*(G11),Settings!$B$18) -> 1192312130 | H12: =MAX(G12,1)/Settings!$B$18 -> 0.5552136 | I12: =-ACE_Input!W12*LN(H12) -> 2.3536095 | J12: =-ACE_Input!X12*LN(H12) -> 7.0608285 | K12: =ACE_Input!U12 -> 300 | L12: =K12*ACE_Input!V12 -> 75
A13: =1 -> 1 | B13: =ACE_Input!A13 -> 8 | C13: =MOD(Settings!$B$17*(C12),Settings!$B$18) -> 965608737 | D13: =MAX(C13,1)/Settings!$B$18 -> 0.44964661 | E13: =F13-F12 -> 5 | F13: =ACE_Input!D13 -> 57 | G13: =MOD(Settings!$B$17*(G12),Settings!$B$18) -> 1020058753 | H13: =MAX(G13,1)/Settings!$B$18 -> 0.47500187 | I13: =-ACE_Input!W13*LN(H13) -> 2.9777461 | J13: =-ACE_Input!X13*LN(H13) -> 8.9332384 | K13: =ACE_Input!U13 -> 300 | L13: =K13*ACE_Input!V13 -> 75
A14: =1 -> 1 | B14: =ACE_Input!A14 -> 9 | C14: =MOD(Settings!$B$17*(C13),Settings!$B$18) -> 452122380 | D14: =MAX(C14,1)/Settings!$B$18 -> 0.21053589 | E14: =F14-F13 -> 115 | F14: =ACE_Input!D14 -> 172 | G14: =MOD(Settings!$B$17*(G13),Settings!$B$18) -> 765507670 | H14: =MAX(G14,1)/Settings!$B$18 -> 0.35646729 | I14: =-ACE_Input!W14*LN(H14) -> 4.1260512 | J14: =-ACE_Input!X14*LN(H14) -> 12.378154 | K14: =ACE_Input!U14 -> 300 | L14: =K14*ACE_Input!V14 -> 75
A15: =1 -> 1 | B15: =ACE_Input!A15 -> 10 | C15: =MOD(Settings!$B$17*(C14),Settings!$B$18) -> 1023697574 | D15: =MAX(C15,1)/Settings!$B$18 -> 0.47669633 | E15: =F15-F14 -> 5 | F15: =ACE_Input!D15 -> 177 | G15: =MOD(Settings!$B$17*(G14),Settings!$B$18) -> 312880513 | H15: =MAX(G15,1)/Settings!$B$18 -> 0.14569634 | I15: =-ACE_Input!W15*LN(H15) -> 7.7049227 | J15: =-ACE_Input!X15*LN(H15) -> 23.114768 | K15: =ACE_Input!U15 -> 300 | L15: =K15*ACE_Input!V15 -> 75
A16: =1 -> 1 | B16: =ACE_Input!A16 -> 11 | C16: =MOD(Settings!$B$17*(C15),Settings!$B$18) -> 1793630101 | D16: =MAX(C16,1)/Settings!$B$18 -> 0.8352241 | E16: =F16-F15 -> 5 | F16: =ACE_Input!D16 -> 182 | G16: =MOD(Settings!$B$17*(G15),Settings!$B$18) -> 1542814135 | H16: =MAX(G16,1)/Settings!$B$18 -> 0.71842882 | I16: =-ACE_Input!W16*LN(H16) -> 1.3227546 | J16: =-ACE_Input!X16*LN(H16) -> 3.9682638 | K16: =ACE_Input!U16 -> 300 | L16: =K16*ACE_Input!V16 -> 75
A17: =1 -> 1 | B17: =ACE_Input!A17 -> 12 | C17: =MOD(Settings!$B$17*(C16),Settings!$B$18) -> 1313154568 | D17: =MAX(C17,1)/Settings!$B$18 -> 0.61148525 | E17: =F17-F16 -> 5 | F17: =ACE_Input!D17 -> 187 | G17: =MOD(Settings!$B$17*(G16),Settings!$B$18) -> 1359613067 | H17: =MAX(G17,1)/Settings!$B$18 -> 0.63311917 | I17: =-ACE_Input!W17*LN(H17) -> 1.8283864 | J17: =-ACE_Input!X17*LN(H17) -> 5.4851593 | K17: =ACE_Input!U17 -> 300 | L17: =K17*ACE_Input!V17 -> 75
A18: =1 -> 1 | B18: =ACE_Input!A18 -> 13 | C18: =MOD(Settings!$B$17*(C17),Settings!$B$18) -> 499384157 | D18: =MAX(C18,1)/Settings!$B$18 -> 0.23254387 | E18: =F18-F17 -> 5 | F18: =ACE_Input!D18 -> 192 | G18: =MOD(Settings!$B$17*(G17),Settings!$B$18) -> 1790812989 | H18: =MAX(G18,1)/Settings!$B$18 -> 0.83391228 | I18: =-ACE_Input!W18*LN(H18) -> 0.72650824 | J18: =-ACE_Input!X18*LN(H18) -> 2.1795247 | K18: =ACE_Input!U18 -> 300 | L18: =K18*ACE_Input!V18 -> 75
... A105: =1 -> 1 | B105: =ACE_Input!A105 -> 100 | C105: =MOD(Settings!$B$17*(C104),Settings!$B$18) -> 947351359 | D105: =MAX(C105,1)/Settings!$B$18 -> 0.44114485 | E105: =F105-F104 -> 5 | F105: =ACE_Input!D105 -> 689 | G105: =MOD(Settings!$B$17*(G104),Settings!$B$18) -> 97771164 | H105: =MAX(G105,1)/Settings!$B$18 -> 0.045528246 | I105: =-ACE_Input!W105*LN(H105) -> 12.357689 | J105: =-ACE_Input!X105*LN(H105) -> 37.073068 | K105: =ACE_Input!U105 -> 300 | L105: =K105*ACE_Input!V105 -> 75
A126: =2 -> 2 | B126: =ACE_Input!A6 -> 1 | C126: =MOD(Settings!$B$17*(Settings!$B$15+1000*A126),Settings!$B$18) -> 241096415 | D126: =MAX(C126,1)/Settings!$B$18 -> 0.11226927 | E126: =F126 -> 2 | F126: =ACE_Input!D6 -> 2 | G126: =MOD(Settings!$B$17*(Settings!$B$16+1000*A126),Settings!$B$18) -> 946587047 | H126: =MAX(G126,1)/Settings!$B$18 -> 0.44078894 | I126: =-ACE_Input!W6*LN(H126) -> 3.2767564 | J126: =-ACE_Input!X6*LN(H126) -> 9.8302693 | K126: =ACE_Input!U6 -> 300 | L126: =K126*ACE_Input!V6 -> 75
A127: =2 -> 2 | B127: =ACE_Input!A7 -> 2 | C127: =MOD(Settings!$B$17*(C126),Settings!$B$18) -> 1953288663 | D127: =MAX(C127,1)/Settings!$B$18 -> 0.90957091 | E127: =F127-F126 -> 5 | F127: =ACE_Input!D7 -> 7 | G127: =MOD(Settings!$B$17*(G126),Settings!$B$18) -> 729641953 | H127: =MAX(G127,1)/Settings!$B$18 -> 0.33976601 | I127: =-ACE_Input!W7*LN(H127) -> 4.3179924 | J127: =-ACE_Input!X7*LN(H127) -> 12.953977 | K127: =ACE_Input!U7 -> 300 | L127: =K127*ACE_Input!V7 -> 75
A128: =2 -> 2 | B128: =ACE_Input!A8 -> 3 | C128: =MOD(Settings!$B$17*(C127),Settings!$B$18) -> 340047352 | D128: =MAX(C128,1)/Settings!$B$18 -> 0.15834689 | E128: =F128-F127 -> 25 | F128: =ACE_Input!D8 -> 32 | G128: =MOD(Settings!$B$17*(G127),Settings!$B$18) -> 960679701 | H128: =MAX(G128,1)/Settings!$B$18 -> 0.44735135 | I128: =-ACE_Input!W8*LN(H128) -> 3.2176439 | J128: =-ACE_Input!X8*LN(H128) -> 9.6529318 | K128: =ACE_Input!U8 -> 300 | L128: =K128*ACE_Input!V8 -> 75
A129: =2 -> 2 | B129: =ACE_Input!A9 -> 4 | C129: =MOD(Settings!$B$17*(C128),Settings!$B$18) -> 721860397 | D129: =MAX(C129,1)/Settings!$B$18 -> 0.33614244 | E129: =F129-F128 -> 5 | F129: =ACE_Input!D9 -> 37 | G129: =MOD(Settings!$B$17*(G128),Settings!$B$18) -> 1361676561 | H129: =MAX(G129,1)/Settings!$B$18 -> 0.63408006 | I129: =-ACE_Input!W9*LN(H129) -> 1.8223202 | J129: =-ACE_Input!X9*LN(H129) -> 5.4669606 | K129: =ACE_Input!U9 -> 300 | L129: =K129*ACE_Input!V9 -> 75
A130: =2 -> 2 | B130: =ACE_Input!A10 -> 5 | C130: =MOD(Settings!$B$17*(C129),Settings!$B$18) -> 1172570476 | D130: =MAX(C130,1)/Settings!$B$18 -> 0.54602068 | E130: =F130-F129 -> 5 | F130: =ACE_Input!D10 -> 42 | G130: =MOD(Settings!$B$17*(G129),Settings!$B$18) -> 2112218295 | H130: =MAX(G130,1)/Settings!$B$18 -> 0.98357829 | I130: =-ACE_Input!W10*LN(H130) -> 0.06623216 | J130: =-ACE_Input!X10*LN(H130) -> 0.19869648 | K130: =ACE_Input!U10 -> 300 | L130: =K130*ACE_Input!V10 -> 75
A131: =2 -> 2 | B131: =ACE_Input!A11 -> 6 | C131: =MOD(Settings!$B$17*(C130),Settings!$B$18) -> 2082045260 | D131: =MAX(C131,1)/Settings!$B$18 -> 0.96952788 | E131: =F131-F130 -> 5 | F131: =ACE_Input!D11 -> 47 | G131: =MOD(Settings!$B$17*(G130),Settings!$B$18) -> 715508 | H131: =MAX(G131,1)/Settings!$B$18 -> 0.00033318438 | I131: =-ACE_Input!W11*LN(H131) -> 32.027258 | J131: =-ACE_Input!X11*LN(H131) -> 96.081774 | K131: =ACE_Input!U11 -> 300 | L131: =K131*ACE_Input!V11 -> 75
A132: =2 -> 2 | B132: =ACE_Input!A12 -> 7 | C132: =MOD(Settings!$B$17*(C131),Settings!$B$18) -> 1836140602 | D132: =MAX(C132,1)/Settings!$B$18 -> 0.8550196 | E132: =F132-F131 -> 5 | F132: =ACE_Input!D12 -> 52 | G132: =MOD(Settings!$B$17*(G131),Settings!$B$18) -> 1288124721 | H132: =MAX(G132,1)/Settings!$B$18 -> 0.59982982 | I132: =-ACE_Input!W12*LN(H132) -> 2.0444372 | J132: =-ACE_Input!X12*LN(H132) -> 6.1333116 | K132: =ACE_Input!U12 -> 300 | L132: =K132*ACE_Input!V12 -> 75
A133: =2 -> 2 | B133: =ACE_Input!A13 -> 8 | C133: =MOD(Settings!$B$17*(C132),Settings!$B$18) -> 675090424 | D133: =MAX(C133,1)/Settings!$B$18 -> 0.31436348 | E133: =F133-F132 -> 5 | F133: =ACE_Input!D13 -> 57 | G133: =MOD(Settings!$B$17*(G132),Settings!$B$18) -> 729540440 | H133: =MAX(G133,1)/Settings!$B$18 -> 0.33971874 | I133: =-ACE_Input!W13*LN(H133) -> 4.3185489 | J133: =-ACE_Input!X13*LN(H133) -> 12.955647 | K133: =ACE_Input!U13 -> 300 | L133: =K133*ACE_Input!V13 -> 75
A134: =2 -> 2 | B134: =ACE_Input!A14 -> 9 | C134: =MOD(Settings!$B$17*(C133),Settings!$B$18) -> 1088649067 | D134: =MAX(C134,1)/Settings!$B$18 -> 0.50694173 | E134: =F134-F133 -> 115 | F134: =ACE_Input!D14 -> 172 | G134: =MOD(Settings!$B$17*(G133),Settings!$B$18) -> 1402034357 | H134: =MAX(G134,1)/Settings!$B$18 -> 0.65287312 | I134: =-ACE_Input!W14*LN(H134) -> 1.7054899 | J134: =-ACE_Input!X14*LN(H134) -> 5.1164696 | K134: =ACE_Input!U14 -> 300 | L134: =K134*ACE_Input!V14 -> 75
A135: =2 -> 2 | B135: =ACE_Input!A15 -> 10 | C135: =MOD(Settings!$B$17*(C134),Settings!$B$18) -> 364196629 | D135: =MAX(C135,1)/Settings!$B$18 -> 0.16959227 | E135: =F135-F134 -> 5 | F135: =ACE_Input!D15 -> 177 | G135: =MOD(Settings!$B$17*(G134),Settings!$B$18) -> 1800863215 | H135: =MAX(G135,1)/Settings!$B$18 -> 0.83859228 | I135: =-ACE_Input!W15*LN(H135) -> 0.70412258 | J135: =-ACE_Input!X15*LN(H135) -> 2.1123678 | K135: =ACE_Input!U15 -> 300 | L135: =K135*ACE_Input!V15 -> 75
A136: =2 -> 2 | B136: =ACE_Input!A16 -> 11 | C136: =MOD(Settings!$B$17*(C135),Settings!$B$18) -> 724349653 | D136: =MAX(C136,1)/Settings!$B$18 -> 0.33730159 | E136: =F136-F135 -> 5 | F136: =ACE_Input!D16 -> 182 | G136: =MOD(Settings!$B$17*(G135),Settings!$B$18) -> 473533687 | H136: =MAX(G136,1)/Settings!$B$18 -> 0.22050631 | I136: =-ACE_Input!W16*LN(H136) -> 6.0473159 | J136: =-ACE_Input!X16*LN(H136) -> 18.141948 | K136: =ACE_Input!U16 -> 300 | L136: =K136*ACE_Input!V16 -> 75
A137: =2 -> 2 | B137: =ACE_Input!A17 -> 12 | C137: =MOD(Settings!$B$17*(C136),Settings!$B$18) -> 59823128 | D137: =MAX(C137,1)/Settings!$B$18 -> 0.027857315 | E137: =F137-F136 -> 5 | F137: =ACE_Input!D17 -> 187 | G137: =MOD(Settings!$B$17*(G136),Settings!$B$18) -> 106281627 | H137: =MAX(G137,1)/Settings!$B$18 -> 0.049491239 | I137: =-ACE_Input!W17*LN(H137) -> 12.023838 | J137: =-ACE_Input!X17*LN(H137) -> 36.071515 | K137: =ACE_Input!U17 -> 300 | L137: =K137*ACE_Input!V17 -> 75
A138: =2 -> 2 | B138: =ACE_Input!A18 -> 13 | C138: =MOD(Settings!$B$17*(C137),Settings!$B$18) -> 424965500 | D138: =MAX(C138,1)/Settings!$B$18 -> 0.19788998 | E138: =F138-F137 -> 5 | F138: =ACE_Input!D18 -> 192 | G138: =MOD(Settings!$B$17*(G137),Settings!$B$18) -> 1716394332 | H138: =MAX(G138,1)/Settings!$B$18 -> 0.79925839 | I138: =-ACE_Input!W18*LN(H138) -> 0.89628395 | J138: =-ACE_Input!X18*LN(H138) -> 2.6888519 | K138: =ACE_Input!U18 -> 300 | L138: =K138*ACE_Input!V18 -> 75
... A225: =2 -> 2 | B225: =ACE_Input!A105 -> 100 | C225: =MOD(Settings!$B$17*(C224),Settings!$B$18) -> 1794781854 | D225: =MAX(C225,1)/Settings!$B$18 -> 0.83576043 | E225: =F225-F224 -> 5 | F225: =ACE_Input!D105 -> 689 | G225: =MOD(Settings!$B$17*(G224),Settings!$B$18) -> 945201659 | H225: =MAX(G225,1)/Settings!$B$18 -> 0.44014382 | I225: =-ACE_Input!W105*LN(H225) -> 3.282615 | J225: =-ACE_Input!X105*LN(H225) -> 9.8478449 | K225: =ACE_Input!U105 -> 300 | L225: =K225*ACE_Input!V105 -> 75
A246: =3 -> 3 | B246: =ACE_Input!A6 -> 1 | C246: =MOD(Settings!$B$17*(Settings!$B$15+1000*A246),Settings!$B$18) -> 257903415 | D246: =MAX(C246,1)/Settings!$B$18 -> 0.12009564 | E246: =F246 -> 2 | F246: =ACE_Input!D6 -> 2 | G246: =MOD(Settings!$B$17*(Settings!$B$16+1000*A246),Settings!$B$18) -> 963394047 | H246: =MAX(G246,1)/Settings!$B$18 -> 0.44861531 | I246: =-ACE_Input!W6*LN(H246) -> 3.2063581 | J246: =-ACE_Input!X6*LN(H246) -> 9.6190743 | K246: =ACE_Input!U6 -> 300 | L246: =K246*ACE_Input!V6 -> 75
A247: =3 -> 3 | B247: =ACE_Input!A7 -> 2 | C247: =MOD(Settings!$B$17*(C246),Settings!$B$18) -> 960696259 | D247: =MAX(C247,1)/Settings!$B$18 -> 0.44735906 | E247: =F247-F246 -> 5 | F247: =ACE_Input!D7 -> 7 | G247: =MOD(Settings!$B$17*(G246),Settings!$B$18) -> 1884533196 | H247: =MAX(G247,1)/Settings!$B$18 -> 0.87755415 | I247: =-ACE_Input!W7*LN(H247) -> 0.52246644 | J247: =-ACE_Input!X7*LN(H247) -> 1.5673993 | K247: =ACE_Input!U7 -> 300 | L247: =K247*ACE_Input!V7 -> 75
A248: =3 -> 3 | B248: =ACE_Input!A8 -> 3 | C248: =MOD(Settings!$B$17*(C247),Settings!$B$18) -> 1639966867 | D248: =MAX(C248,1)/Settings!$B$18 -> 0.76366908 | E248: =F248-F247 -> 25 | F248: =ACE_Input!D8 -> 32 | G248: =MOD(Settings!$B$17*(G247),Settings!$B$18) -> 113115569 | H248: =MAX(G248,1)/Settings!$B$18 -> 0.052673541 | I248: =-ACE_Input!W8*LN(H248) -> 11.774568 | J248: =-ACE_Input!X8*LN(H248) -> 35.323704 | K248: =ACE_Input!U8 -> 300 | L248: =K248*ACE_Input!V8 -> 75
A249: =3 -> 3 | B249: =ACE_Input!A9 -> 4 | C249: =MOD(Settings!$B$17*(C248),Settings!$B$18) -> 2118008071 | D249: =MAX(C249,1)/Settings!$B$18 -> 0.98627437 | E249: =F249-F248 -> 5 | F249: =ACE_Input!D9 -> 37 | G249: =MOD(Settings!$B$17*(G248),Settings!$B$18) -> 610340588 | H249: =MAX(G249,1)/Settings!$B$18 -> 0.28421198 | I249: =-ACE_Input!W9*LN(H249) -> 5.0321396 | J249: =-ACE_Input!X9*LN(H249) -> 15.096419 | K249: =ACE_Input!U9 -> 300 | L249: =K249*ACE_Input!V9 -> 75
A250: =3 -> 3 | B250: =ACE_Input!A10 -> 5 | C250: =MOD(Settings!$B$17*(C249),Settings!$B$18) -> 672716625 | D250: =MAX(C250,1)/Settings!$B$18 -> 0.31325809 | E250: =F250-F249 -> 5 | F250: =ACE_Input!D10 -> 42 | G250: =MOD(Settings!$B$17*(G249),Settings!$B$18) -> 1612364444 | H250: =MAX(G250,1)/Settings!$B$18 -> 0.7508157 | I250: =-ACE_Input!W10*LN(H250) -> 1.1463802 | J250: =-ACE_Input!X10*LN(H250) -> 3.4391407 | K250: =ACE_Input!U10 -> 300 | L250: =K250*ACE_Input!V10 -> 75
A251: =3 -> 3 | B251: =ACE_Input!A11 -> 6 | C251: =MOD(Settings!$B$17*(C250),Settings!$B$18) -> 1994398567 | D251: =MAX(C251,1)/Settings!$B$18 -> 0.9287142 | E251: =F251-F250 -> 5 | F251: =ACE_Input!D11 -> 47 | G251: =MOD(Settings!$B$17*(G250),Settings!$B$18) -> 2060552462 | H251: =MAX(G251,1)/Settings!$B$18 -> 0.95951951 | I251: =-ACE_Input!W11*LN(H251) -> 0.16529051 | J251: =-ACE_Input!X11*LN(H251) -> 0.49587153 | K251: =ACE_Input!U11 -> 300 | L251: =K251*ACE_Input!V11 -> 75
A252: =3 -> 3 | B252: =ACE_Input!A12 -> 7 | C252: =MOD(Settings!$B$17*(C251),Settings!$B$18) -> 1931953193 | D252: =MAX(C252,1)/Settings!$B$18 -> 0.89963581 | E252: =F252-F251 -> 5 | F252: =ACE_Input!D12 -> 52 | G252: =MOD(Settings!$B$17*(G251),Settings!$B$18) -> 1383937312 | H252: =MAX(G252,1)/Settings!$B$18 -> 0.64444603 | I252: =-ACE_Input!W12*LN(H252) -> 1.7574568 | J252: =-ACE_Input!X12*LN(H252) -> 5.2723704 | K252: =ACE_Input!U12 -> 300 | L252: =K252*ACE_Input!V12 -> 75
A253: =3 -> 3 | B253: =ACE_Input!A13 -> 8 | C253: =MOD(Settings!$B$17*(C252),Settings!$B$18) -> 384572111 | D253: =MAX(C253,1)/Settings!$B$18 -> 0.17908034 | E253: =F253-F252 -> 5 | F253: =ACE_Input!D13 -> 57 | G253: =MOD(Settings!$B$17*(G252),Settings!$B$18) -> 439022127 | H253: =MAX(G253,1)/Settings!$B$18 -> 0.20443561 | I253: =-ACE_Input!W13*LN(H253) -> 6.3500089 | J253: =-ACE_Input!X13*LN(H253) -> 19.050027 | K253: =ACE_Input!U13 -> 300 | L253: =K253*ACE_Input!V13 -> 75
A254: =3 -> 3 | B254: =ACE_Input!A14 -> 9 | C254: =MOD(Settings!$B$17*(C253),Settings!$B$18) -> 1725175754 | D254: =MAX(C254,1)/Settings!$B$18 -> 0.80334756 | E254: =F254-F253 -> 115 | F254: =ACE_Input!D14 -> 172 | G254: =MOD(Settings!$B$17*(G253),Settings!$B$18) -> 2038561044 | H254: =MAX(G254,1)/Settings!$B$18 -> 0.94927896 | I254: =-ACE_Input!W14*LN(H254) -> 0.20821029 | J254: =-ACE_Input!X14*LN(H254) -> 0.62463086 | K254: =ACE_Input!U14 -> 300 | L254: =K254*ACE_Input!V14 -> 75
...

Sheet RGS_Ground_Run
A1: Ground_Run - arrive > wait for link > downlink full volume > ground processing > delivered
A2: CONDITIONAL SYNTHETIC PERFORMANCE. Stale flags do not cancel jobs; mean completion times include stale-flagged work. No historical OPS-SAT latency or outage is measured here.
A5: Rep | B5: Entity | C5: Arrival (s) | D5: Volume (MB) | E5: Transmit time (s) | F5: Link ready (s) | G5: Link free at (s) | H5: Earliest link start (s) | I5: Cycle phase (s) | J5: Link start (s) | K5: Link done (s) | L5: Processor ready (s) | M5: Processor free at (s) | N5: Processor start (s) | O5: Processing time (s) | P5: Delivered (s) | Q5: End-to-end latency (s) | R5: Wait in link queue (s) | S5: Wait for link recovery (s) | T5: Wait for processor (s) | U5: Total queueing delay (s) | V5: Link state at arrival | W5: Delivered flag | X5: Within deadline
A6: =Arrivals!A6 -> 1 | B6: =Arrivals!B6 -> 1 | C6: =Arrivals!F6 -> 2 | D6: =Arrivals!K6 -> 300 | E6: =D6*8/ACE_Input!S6+ACE_Input!T6 -> 24.02 | F6: =C6 -> 2 | G6: =0 -> 0 | H6: =MAX(F6,G6) -> 2 | I6: =MOD(H6-Settings!$B$32,Settings!$B$33) -> 2 | J6: =IF(I6<Settings!$B$30,IF(Settings!$B$30-I6>=E6,H6,H6+(Settings!$B$30-I6)+Settings!$B$31),H6+(Settings!$B$33-I6)) -> 2 | K6: =J6+E6 -> 26.02 | L6: =K6 -> 26.02 | M6: =0 -> 0 | N6: =MAX(L6,M6) -> 26.02 | O6: =Arrivals!I6 -> 3.348416 | P6: =N6+O6 -> 29.368416 | Q6: =P6-C6 -> 27.368416 | R6: =H6-F6 -> 0 | S6: =J6-H6 -> 0 | T6: =N6-L6 -> 0 | U6: =R6+S6+T6 -> 0 | V6: =IF(MOD(C6-Settings!$B$32,Settings!$B$33)<Settings!$B$30,"Up","Down") -> Up | W6: =IF(OR(E6>Settings!$B$30,Q6>Settings!$B$37),0,1) -> 1 | X6: =IF(AND(W6=1,Q6<=Settings!$B$36),1,0) -> 1
A7: =Arrivals!A7 -> 1 | B7: =Arrivals!B7 -> 2 | C7: =Arrivals!F7 -> 7 | D7: =Arrivals!K7 -> 300 | E7: =D7*8/ACE_Input!S7+ACE_Input!T7 -> 24.02 | F7: =C7 -> 7 | G7: =K6 -> 26.02 | H7: =MAX(F7,G7) -> 26.02 | I7: =MOD(H7-Settings!$B$32,Settings!$B$33) -> 26.02 | J7: =IF(I7<Settings!$B$30,IF(Settings!$B$30-I7>=E7,H7,H7+(Settings!$B$30-I7)+Settings!$B$31),H7+(Settings!$B$33-I7)) -> 26.02 | K7: =J7+E7 -> 50.04 | L7: =K7 -> 50.04 | M7: =P6 -> 29.368416 | N7: =MAX(L7,M7) -> 50.04 | O7: =Arrivals!I7 -> 0.88269707 | P7: =N7+O7 -> 50.922697 | Q7: =P7-C7 -> 43.922697 | R7: =H7-F7 -> 19.02 | S7: =J7-H7 -> 0 | T7: =N7-L7 -> 0 | U7: =R7+S7+T7 -> 19.02 | V7: =IF(MOD(C7-Settings!$B$32,Settings!$B$33)<Settings!$B$30,"Up","Down") -> Up | W7: =IF(OR(E7>Settings!$B$30,Q7>Settings!$B$37),0,1) -> 1 | X7: =IF(AND(W7=1,Q7<=Settings!$B$36),1,0) -> 1
A8: =Arrivals!A8 -> 1 | B8: =Arrivals!B8 -> 3 | C8: =Arrivals!F8 -> 32 | D8: =Arrivals!K8 -> 300 | E8: =D8*8/ACE_Input!S8+ACE_Input!T8 -> 24.02 | F8: =C8 -> 32 | G8: =K7 -> 50.04 | H8: =MAX(F8,G8) -> 50.04 | I8: =MOD(H8-Settings!$B$32,Settings!$B$33) -> 50.04 | J8: =IF(I8<Settings!$B$30,IF(Settings!$B$30-I8>=E8,H8,H8+(Settings!$B$30-I8)+Settings!$B$31),H8+(Settings!$B$33-I8)) -> 50.04 | K8: =J8+E8 -> 74.06 | L8: =K8 -> 74.06 | M8: =P7 -> 50.922697 | N8: =MAX(L8,M8) -> 74.06 | O8: =Arrivals!I8 -> 0.68776257 | P8: =N8+O8 -> 74.747763 | Q8: =P8-C8 -> 42.747763 | R8: =H8-F8 -> 18.04 | S8: =J8-H8 -> 0 | T8: =N8-L8 -> 0 | U8: =R8+S8+T8 -> 18.04 | V8: =IF(MOD(C8-Settings!$B$32,Settings!$B$33)<Settings!$B$30,"Up","Down") -> Up | W8: =IF(OR(E8>Settings!$B$30,Q8>Settings!$B$37),0,1) -> 1 | X8: =IF(AND(W8=1,Q8<=Settings!$B$36),1,0) -> 1
A9: =Arrivals!A9 -> 1 | B9: =Arrivals!B9 -> 4 | C9: =Arrivals!F9 -> 37 | D9: =Arrivals!K9 -> 300 | E9: =D9*8/ACE_Input!S9+ACE_Input!T9 -> 24.02 | F9: =C9 -> 37 | G9: =K8 -> 74.06 | H9: =MAX(F9,G9) -> 74.06 | I9: =MOD(H9-Settings!$B$32,Settings!$B$33) -> 74.06 | J9: =IF(I9<Settings!$B$30,IF(Settings!$B$30-I9>=E9,H9,H9+(Settings!$B$30-I9)+Settings!$B$31),H9+(Settings!$B$33-I9)) -> 74.06 | K9: =J9+E9 -> 98.08 | L9: =K9 -> 98.08 | M9: =P8 -> 74.747763 | N9: =MAX(L9,M9) -> 98.08 | O9: =Arrivals!I9 -> 0.064728358 | P9: =N9+O9 -> 98.144728 | Q9: =P9-C9 -> 61.144728 | R9: =H9-F9 -> 37.06 | S9: =J9-H9 -> 0 | T9: =N9-L9 -> 0 | U9: =R9+S9+T9 -> 37.06 | V9: =IF(MOD(C9-Settings!$B$32,Settings!$B$33)<Settings!$B$30,"Up","Down") -> Up | W9: =IF(OR(E9>Settings!$B$30,Q9>Settings!$B$37),0,1) -> 1 | X9: =IF(AND(W9=1,Q9<=Settings!$B$36),1,0) -> 1
A10: =Arrivals!A10 -> 1 | B10: =Arrivals!B10 -> 5 | C10: =Arrivals!F10 -> 42 | D10: =Arrivals!K10 -> 300 | E10: =D10*8/ACE_Input!S10+ACE_Input!T10 -> 24.02 | F10: =C10 -> 42 | G10: =K9 -> 98.08 | H10: =MAX(F10,G10) -> 98.08 | I10: =MOD(H10-Settings!$B$32,Settings!$B$33) -> 98.08 | J10: =IF(I10<Settings!$B$30,IF(Settings!$B$30-I10>=E10,H10,H10+(Settings!$B$30-I10)+Settings!$B$31),H10+(Settings!$B$33-I10)) -> 98.08 | K10: =J10+E10 -> 122.1 | L10: =K10 -> 122.1 | M10: =P9 -> 98.144728 | N10: =MAX(L10,M10) -> 122.1 | O10: =Arrivals!I10 -> 6.1235999 | P10: =N10+O10 -> 128.2236 | Q10: =P10-C10 -> 86.2236 | R10: =H10-F10 -> 56.08 | S10: =J10-H10 -> 0 | T10: =N10-L10 -> 0 | U10: =R10+S10+T10 -> 56.08 | V10: =IF(MOD(C10-Settings!$B$32,Settings!$B$33)<Settings!$B$30,"Up","Down") -> Up | W10: =IF(OR(E10>Settings!$B$30,Q10>Settings!$B$37),0,1) -> 1 | X10: =IF(AND(W10=1,Q10<=Settings!$B$36),1,0) -> 1
A11: =Arrivals!A11 -> 1 | B11: =Arrivals!B11 -> 6 | C11: =Arrivals!F11 -> 47 | D11: =Arrivals!K11 -> 300 | E11: =D11*8/ACE_Input!S11+ACE_Input!T11 -> 24.02 | F11: =C11 -> 47 | G11: =K10 -> 122.1 | H11: =MAX(F11,G11) -> 122.1 | I11: =MOD(H11-Settings!$B$32,Settings!$B$33) -> 122.1 | J11: =IF(I11<Settings!$B$30,IF(Settings!$B$30-I11>=E11,H11,H11+(Settings!$B$30-I11)+Settings!$B$31),H11+(Settings!$B$33-I11)) -> 122.1 | K11: =J11+E11 -> 146.12 | L11: =K11 -> 146.12 | M11: =P10 -> 128.2236 | N11: =MAX(L11,M11) -> 146.12 | O11: =Arrivals!I11 -> 12.762431 | P11: =N11+O11 -> 158.88243 | Q11: =P11-C11 -> 111.88243 | R11: =H11-F11 -> 75.1 | S11: =J11-H11 -> 0 | T11: =N11-L11 -> 0 | U11: =R11+S11+T11 -> 75.1 | V11: =IF(MOD(C11-Settings!$B$32,Settings!$B$33)<Settings!$B$30,"Up","Down") -> Up | W11: =IF(OR(E11>Settings!$B$30,Q11>Settings!$B$37),0,1) -> 1 | X11: =IF(AND(W11=1,Q11<=Settings!$B$36),1,0) -> 1
A12: =Arrivals!A12 -> 1 | B12: =Arrivals!B12 -> 7 | C12: =Arrivals!F12 -> 52 | D12: =Arrivals!K12 -> 300 | E12: =D12*8/ACE_Input!S12+ACE_Input!T12 -> 24.02 | F12: =C12 -> 52 | G12: =K11 -> 146.12 | H12: =MAX(F12,G12) -> 146.12 | I12: =MOD(H12-Settings!$B$32,Settings!$B$33) -> 146.12 | J12: =IF(I12<Settings!$B$30,IF(Settings!$B$30-I12>=E12,H12,H12+(Settings!$B$30-I12)+Settings!$B$31),H12+(Settings!$B$33-I12)) -> 146.12 | K12: =J12+E12 -> 170.14 | L12: =K12 -> 170.14 | M12: =P11 -> 158.88243 | N12: =MAX(L12,M12) -> 170.14 | O12: =Arrivals!I12 -> 2.3536095 | P12: =N12+O12 -> 172.49361 | Q12: =P12-C12 -> 120.49361 | R12: =H12-F12 -> 94.12 | S12: =J12-H12 -> 0 | T12: =N12-L12 -> 0 | U12: =R12+S12+T12 -> 94.12 | V12: =IF(MOD(C12-Settings!$B$32,Settings!$B$33)<Settings!$B$30,"Up","Down") -> Up | W12: =IF(OR(E12>Settings!$B$30,Q12>Settings!$B$37),0,1) -> 1 | X12: =IF(AND(W12=1,Q12<=Settings!$B$36),1,0) -> 0
A13: =Arrivals!A13 -> 1 | B13: =Arrivals!B13 -> 8 | C13: =Arrivals!F13 -> 57 | D13: =Arrivals!K13 -> 300 | E13: =D13*8/ACE_Input!S13+ACE_Input!T13 -> 24.02 | F13: =C13 -> 57 | G13: =K12 -> 170.14 | H13: =MAX(F13,G13) -> 170.14 | I13: =MOD(H13-Settings!$B$32,Settings!$B$33) -> 170.14 | J13: =IF(I13<Settings!$B$30,IF(Settings!$B$30-I13>=E13,H13,H13+(Settings!$B$30-I13)+Settings!$B$31),H13+(Settings!$B$33-I13)) -> 170.14 | K13: =J13+E13 -> 194.16 | L13: =K13 -> 194.16 | M13: =P12 -> 172.49361 | N13: =MAX(L13,M13) -> 194.16 | O13: =Arrivals!I13 -> 2.9777461 | P13: =N13+O13 -> 197.13775 | Q13: =P13-C13 -> 140.13775 | R13: =H13-F13 -> 113.14 | S13: =J13-H13 -> 0 | T13: =N13-L13 -> 0 | U13: =R13+S13+T13 -> 113.14 | V13: =IF(MOD(C13-Settings!$B$32,Settings!$B$33)<Settings!$B$30,"Up","Down") -> Up | W13: =IF(OR(E13>Settings!$B$30,Q13>Settings!$B$37),0,1) -> 1 | X13: =IF(AND(W13=1,Q13<=Settings!$B$36),1,0) -> 0
A14: =Arrivals!A14 -> 1 | B14: =Arrivals!B14 -> 9 | C14: =Arrivals!F14 -> 172 | D14: =Arrivals!K14 -> 300 | E14: =D14*8/ACE_Input!S14+ACE_Input!T14 -> 24.02 | F14: =C14 -> 172 | G14: =K13 -> 194.16 | H14: =MAX(F14,G14) -> 194.16 | I14: =MOD(H14-Settings!$B$32,Settings!$B$33) -> 194.16 | J14: =IF(I14<Settings!$B$30,IF(Settings!$B$30-I14>=E14,H14,H14+(Settings!$B$30-I14)+Settings!$B$31),H14+(Settings!$B$33-I14)) -> 194.16 | K14: =J14+E14 -> 218.18 | L14: =K14 -> 218.18 | M14: =P13 -> 197.13775 | N14: =MAX(L14,M14) -> 218.18 | O14: =Arrivals!I14 -> 4.1260512 | P14: =N14+O14 -> 222.30605 | Q14: =P14-C14 -> 50.306051 | R14: =H14-F14 -> 22.16 | S14: =J14-H14 -> 0 | T14: =N14-L14 -> 0 | U14: =R14+S14+T14 -> 22.16 | V14: =IF(MOD(C14-Settings!$B$32,Settings!$B$33)<Settings!$B$30,"Up","Down") -> Up | W14: =IF(OR(E14>Settings!$B$30,Q14>Settings!$B$37),0,1) -> 1 | X14: =IF(AND(W14=1,Q14<=Settings!$B$36),1,0) -> 1
A15: =Arrivals!A15 -> 1 | B15: =Arrivals!B15 -> 10 | C15: =Arrivals!F15 -> 177 | D15: =Arrivals!K15 -> 300 | E15: =D15*8/ACE_Input!S15+ACE_Input!T15 -> 24.02 | F15: =C15 -> 177 | G15: =K14 -> 218.18 | H15: =MAX(F15,G15) -> 218.18 | I15: =MOD(H15-Settings!$B$32,Settings!$B$33) -> 218.18 | J15: =IF(I15<Settings!$B$30,IF(Settings!$B$30-I15>=E15,H15,H15+(Settings!$B$30-I15)+Settings!$B$31),H15+(Settings!$B$33-I15)) -> 218.18 | K15: =J15+E15 -> 242.2 | L15: =K15 -> 242.2 | M15: =P14 -> 222.30605 | N15: =MAX(L15,M15) -> 242.2 | O15: =Arrivals!I15 -> 7.7049227 | P15: =N15+O15 -> 249.90492 | Q15: =P15-C15 -> 72.904923 | R15: =H15-F15 -> 41.18 | S15: =J15-H15 -> 0 | T15: =N15-L15 -> 0 | U15: =R15+S15+T15 -> 41.18 | V15: =IF(MOD(C15-Settings!$B$32,Settings!$B$33)<Settings!$B$30,"Up","Down") -> Up | W15: =IF(OR(E15>Settings!$B$30,Q15>Settings!$B$37),0,1) -> 1 | X15: =IF(AND(W15=1,Q15<=Settings!$B$36),1,0) -> 1
A16: =Arrivals!A16 -> 1 | B16: =Arrivals!B16 -> 11 | C16: =Arrivals!F16 -> 182 | D16: =Arrivals!K16 -> 300 | E16: =D16*8/ACE_Input!S16+ACE_Input!T16 -> 24.02 | F16: =C16 -> 182 | G16: =K15 -> 242.2 | H16: =MAX(F16,G16) -> 242.2 | I16: =MOD(H16-Settings!$B$32,Settings!$B$33) -> 242.2 | J16: =IF(I16<Settings!$B$30,IF(Settings!$B$30-I16>=E16,H16,H16+(Settings!$B$30-I16)+Settings!$B$31),H16+(Settings!$B$33-I16)) -> 242.2 | K16: =J16+E16 -> 266.22 | L16: =K16 -> 266.22 | M16: =P15 -> 249.90492 | N16: =MAX(L16,M16) -> 266.22 | O16: =Arrivals!I16 -> 1.3227546 | P16: =N16+O16 -> 267.54275 | Q16: =P16-C16 -> 85.542755 | R16: =H16-F16 -> 60.2 | S16: =J16-H16 -> 0 | T16: =N16-L16 -> 0 | U16: =R16+S16+T16 -> 60.2 | V16: =IF(MOD(C16-Settings!$B$32,Settings!$B$33)<Settings!$B$30,"Up","Down") -> Up | W16: =IF(OR(E16>Settings!$B$30,Q16>Settings!$B$37),0,1) -> 1 | X16: =IF(AND(W16=1,Q16<=Settings!$B$36),1,0) -> 1
A17: =Arrivals!A17 -> 1 | B17: =Arrivals!B17 -> 12 | C17: =Arrivals!F17 -> 187 | D17: =Arrivals!K17 -> 300 | E17: =D17*8/ACE_Input!S17+ACE_Input!T17 -> 24.02 | F17: =C17 -> 187 | G17: =K16 -> 266.22 | H17: =MAX(F17,G17) -> 266.22 | I17: =MOD(H17-Settings!$B$32,Settings!$B$33) -> 266.22 | J17: =IF(I17<Settings!$B$30,IF(Settings!$B$30-I17>=E17,H17,H17+(Settings!$B$30-I17)+Settings!$B$31),H17+(Settings!$B$33-I17)) -> 266.22 | K17: =J17+E17 -> 290.24 | L17: =K17 -> 290.24 | M17: =P16 -> 267.54275 | N17: =MAX(L17,M17) -> 290.24 | O17: =Arrivals!I17 -> 1.8283864 | P17: =N17+O17 -> 292.06839 | Q17: =P17-C17 -> 105.06839 | R17: =H17-F17 -> 79.22 | S17: =J17-H17 -> 0 | T17: =N17-L17 -> 0 | U17: =R17+S17+T17 -> 79.22 | V17: =IF(MOD(C17-Settings!$B$32,Settings!$B$33)<Settings!$B$30,"Up","Down") -> Up | W17: =IF(OR(E17>Settings!$B$30,Q17>Settings!$B$37),0,1) -> 1 | X17: =IF(AND(W17=1,Q17<=Settings!$B$36),1,0) -> 1
A18: =Arrivals!A18 -> 1 | B18: =Arrivals!B18 -> 13 | C18: =Arrivals!F18 -> 192 | D18: =Arrivals!K18 -> 300 | E18: =D18*8/ACE_Input!S18+ACE_Input!T18 -> 24.02 | F18: =C18 -> 192 | G18: =K17 -> 290.24 | H18: =MAX(F18,G18) -> 290.24 | I18: =MOD(H18-Settings!$B$32,Settings!$B$33) -> 290.24 | J18: =IF(I18<Settings!$B$30,IF(Settings!$B$30-I18>=E18,H18,H18+(Settings!$B$30-I18)+Settings!$B$31),H18+(Settings!$B$33-I18)) -> 290.24 | K18: =J18+E18 -> 314.26 | L18: =K18 -> 314.26 | M18: =P17 -> 292.06839 | N18: =MAX(L18,M18) -> 314.26 | O18: =Arrivals!I18 -> 0.72650824 | P18: =N18+O18 -> 314.98651 | Q18: =P18-C18 -> 122.98651 | R18: =H18-F18 -> 98.24 | S18: =J18-H18 -> 0 | T18: =N18-L18 -> 0 | U18: =R18+S18+T18 -> 98.24 | V18: =IF(MOD(C18-Settings!$B$32,Settings!$B$33)<Settings!$B$30,"Up","Down") -> Up | W18: =IF(OR(E18>Settings!$B$30,Q18>Settings!$B$37),0,1) -> 1 | X18: =IF(AND(W18=1,Q18<=Settings!$B$36),1,0) -> 0
... A105: =Arrivals!A105 -> 1 | B105: =Arrivals!B105 -> 100 | C105: =Arrivals!F105 -> 689 | D105: =Arrivals!K105 -> 300 | E105: =D105*8/ACE_Input!S105+ACE_Input!T105 -> 24.02 | F105: =C105 -> 689 | G105: =K104 -> 2952.06 | H105: =MAX(F105,G105) -> 2952.06 | I105: =MOD(H105-Settings!$B$32,Settings!$B$33) -> 72.06 | J105: =IF(I105<Settings!$B$30,IF(Settings!$B$30-I105>=E105,H105,H105+(Settings!$B$30-I105)+Settings!$B$31),H105+(Settings!$B$33-I105)) -> 2952.06 | K105: =J105+E105 -> 2976.08 | L105: =K105 -> 2976.08 | M105: =P104 -> 2952.4778 | N105: =MAX(L105,M105) -> 2976.08 | O105: =Arrivals!I105 -> 12.357689 | P105: =N105+O105 -> 2988.4377 | Q105: =P105-C105 -> 2299.4377 | R105: =H105-F105 -> 2263.06 | S105: =J105-H105 -> 0 | T105: =N105-L105 -> 0 | U105: =R105+S105+T105 -> 2263.06 | V105: =IF(MOD(C105-Settings!$B$32,Settings!$B$33)<Settings!$B$30,"Up","Down") -> Down | W105: =IF(OR(E105>Settings!$B$30,Q105>Settings!$B$37),0,1) -> 0 | X105: =IF(AND(W105=1,Q105<=Settings!$B$36),1,0) -> 0
A126: =Arrivals!A126 -> 2 | B126: =Arrivals!B126 -> 1 | C126: =Arrivals!F126 -> 2 | D126: =Arrivals!K126 -> 300 | E126: =D126*8/ACE_Input!S6+ACE_Input!T6 -> 24.02 | F126: =C126 -> 2 | G126: =0 -> 0 | H126: =MAX(F126,G126) -> 2 | I126: =MOD(H126-Settings!$B$32,Settings!$B$33) -> 2 | J126: =IF(I126<Settings!$B$30,IF(Settings!$B$30-I126>=E126,H126,H126+(Settings!$B$30-I126)+Settings!$B$31),H126+(Settings!$B$33-I126)) -> 2 | K126: =J126+E126 -> 26.02 | L126: =K126 -> 26.02 | M126: =0 -> 0 | N126: =MAX(L126,M126) -> 26.02 | O126: =Arrivals!I126 -> 3.2767564 | P126: =N126+O126 -> 29.296756 | Q126: =P126-C126 -> 27.296756 | R126: =H126-F126 -> 0 | S126: =J126-H126 -> 0 | T126: =N126-L126 -> 0 | U126: =R126+S126+T126 -> 0 | V126: =IF(MOD(C126-Settings!$B$32,Settings!$B$33)<Settings!$B$30,"Up","Down") -> Up | W126: =IF(OR(E126>Settings!$B$30,Q126>Settings!$B$37),0,1) -> 1 | X126: =IF(AND(W126=1,Q126<=Settings!$B$36),1,0) -> 1
A127: =Arrivals!A127 -> 2 | B127: =Arrivals!B127 -> 2 | C127: =Arrivals!F127 -> 7 | D127: =Arrivals!K127 -> 300 | E127: =D127*8/ACE_Input!S7+ACE_Input!T7 -> 24.02 | F127: =C127 -> 7 | G127: =K126 -> 26.02 | H127: =MAX(F127,G127) -> 26.02 | I127: =MOD(H127-Settings!$B$32,Settings!$B$33) -> 26.02 | J127: =IF(I127<Settings!$B$30,IF(Settings!$B$30-I127>=E127,H127,H127+(Settings!$B$30-I127)+Settings!$B$31),H127+(Settings!$B$33-I127)) -> 26.02 | K127: =J127+E127 -> 50.04 | L127: =K127 -> 50.04 | M127: =P126 -> 29.296756 | N127: =MAX(L127,M127) -> 50.04 | O127: =Arrivals!I127 -> 4.3179924 | P127: =N127+O127 -> 54.357992 | Q127: =P127-C127 -> 47.357992 | R127: =H127-F127 -> 19.02 | S127: =J127-H127 -> 0 | T127: =N127-L127 -> 0 | U127: =R127+S127+T127 -> 19.02 | V127: =IF(MOD(C127-Settings!$B$32,Settings!$B$33)<Settings!$B$30,"Up","Down") -> Up | W127: =IF(OR(E127>Settings!$B$30,Q127>Settings!$B$37),0,1) -> 1 | X127: =IF(AND(W127=1,Q127<=Settings!$B$36),1,0) -> 1
A128: =Arrivals!A128 -> 2 | B128: =Arrivals!B128 -> 3 | C128: =Arrivals!F128 -> 32 | D128: =Arrivals!K128 -> 300 | E128: =D128*8/ACE_Input!S8+ACE_Input!T8 -> 24.02 | F128: =C128 -> 32 | G128: =K127 -> 50.04 | H128: =MAX(F128,G128) -> 50.04 | I128: =MOD(H128-Settings!$B$32,Settings!$B$33) -> 50.04 | J128: =IF(I128<Settings!$B$30,IF(Settings!$B$30-I128>=E128,H128,H128+(Settings!$B$30-I128)+Settings!$B$31),H128+(Settings!$B$33-I128)) -> 50.04 | K128: =J128+E128 -> 74.06 | L128: =K128 -> 74.06 | M128: =P127 -> 54.357992 | N128: =MAX(L128,M128) -> 74.06 | O128: =Arrivals!I128 -> 3.2176439 | P128: =N128+O128 -> 77.277644 | Q128: =P128-C128 -> 45.277644 | R128: =H128-F128 -> 18.04 | S128: =J128-H128 -> 0 | T128: =N128-L128 -> 0 | U128: =R128+S128+T128 -> 18.04 | V128: =IF(MOD(C128-Settings!$B$32,Settings!$B$33)<Settings!$B$30,"Up","Down") -> Up | W128: =IF(OR(E128>Settings!$B$30,Q128>Settings!$B$37),0,1) -> 1 | X128: =IF(AND(W128=1,Q128<=Settings!$B$36),1,0) -> 1
A129: =Arrivals!A129 -> 2 | B129: =Arrivals!B129 -> 4 | C129: =Arrivals!F129 -> 37 | D129: =Arrivals!K129 -> 300 | E129: =D129*8/ACE_Input!S9+ACE_Input!T9 -> 24.02 | F129: =C129 -> 37 | G129: =K128 -> 74.06 | H129: =MAX(F129,G129) -> 74.06 | I129: =MOD(H129-Settings!$B$32,Settings!$B$33) -> 74.06 | J129: =IF(I129<Settings!$B$30,IF(Settings!$B$30-I129>=E129,H129,H129+(Settings!$B$30-I129)+Settings!$B$31),H129+(Settings!$B$33-I129)) -> 74.06 | K129: =J129+E129 -> 98.08 | L129: =K129 -> 98.08 | M129: =P128 -> 77.277644 | N129: =MAX(L129,M129) -> 98.08 | O129: =Arrivals!I129 -> 1.8223202 | P129: =N129+O129 -> 99.90232 | Q129: =P129-C129 -> 62.90232 | R129: =H129-F129 -> 37.06 | S129: =J129-H129 -> 0 | T129: =N129-L129 -> 0 | U129: =R129+S129+T129 -> 37.06 | V129: =IF(MOD(C129-Settings!$B$32,Settings!$B$33)<Settings!$B$30,"Up","Down") -> Up | W129: =IF(OR(E129>Settings!$B$30,Q129>Settings!$B$37),0,1) -> 1 | X129: =IF(AND(W129=1,Q129<=Settings!$B$36),1,0) -> 1
A130: =Arrivals!A130 -> 2 | B130: =Arrivals!B130 -> 5 | C130: =Arrivals!F130 -> 42 | D130: =Arrivals!K130 -> 300 | E130: =D130*8/ACE_Input!S10+ACE_Input!T10 -> 24.02 | F130: =C130 -> 42 | G130: =K129 -> 98.08 | H130: =MAX(F130,G130) -> 98.08 | I130: =MOD(H130-Settings!$B$32,Settings!$B$33) -> 98.08 | J130: =IF(I130<Settings!$B$30,IF(Settings!$B$30-I130>=E130,H130,H130+(Settings!$B$30-I130)+Settings!$B$31),H130+(Settings!$B$33-I130)) -> 98.08 | K130: =J130+E130 -> 122.1 | L130: =K130 -> 122.1 | M130: =P129 -> 99.90232 | N130: =MAX(L130,M130) -> 122.1 | O130: =Arrivals!I130 -> 0.06623216 | P130: =N130+O130 -> 122.16623 | Q130: =P130-C130 -> 80.166232 | R130: =H130-F130 -> 56.08 | S130: =J130-H130 -> 0 | T130: =N130-L130 -> 0 | U130: =R130+S130+T130 -> 56.08 | V130: =IF(MOD(C130-Settings!$B$32,Settings!$B$33)<Settings!$B$30,"Up","Down") -> Up | W130: =IF(OR(E130>Settings!$B$30,Q130>Settings!$B$37),0,1) -> 1 | X130: =IF(AND(W130=1,Q130<=Settings!$B$36),1,0) -> 1
A131: =Arrivals!A131 -> 2 | B131: =Arrivals!B131 -> 6 | C131: =Arrivals!F131 -> 47 | D131: =Arrivals!K131 -> 300 | E131: =D131*8/ACE_Input!S11+ACE_Input!T11 -> 24.02 | F131: =C131 -> 47 | G131: =K130 -> 122.1 | H131: =MAX(F131,G131) -> 122.1 | I131: =MOD(H131-Settings!$B$32,Settings!$B$33) -> 122.1 | J131: =IF(I131<Settings!$B$30,IF(Settings!$B$30-I131>=E131,H131,H131+(Settings!$B$30-I131)+Settings!$B$31),H131+(Settings!$B$33-I131)) -> 122.1 | K131: =J131+E131 -> 146.12 | L131: =K131 -> 146.12 | M131: =P130 -> 122.16623 | N131: =MAX(L131,M131) -> 146.12 | O131: =Arrivals!I131 -> 32.027258 | P131: =N131+O131 -> 178.14726 | Q131: =P131-C131 -> 131.14726 | R131: =H131-F131 -> 75.1 | S131: =J131-H131 -> 0 | T131: =N131-L131 -> 0 | U131: =R131+S131+T131 -> 75.1 | V131: =IF(MOD(C131-Settings!$B$32,Settings!$B$33)<Settings!$B$30,"Up","Down") -> Up | W131: =IF(OR(E131>Settings!$B$30,Q131>Settings!$B$37),0,1) -> 1 | X131: =IF(AND(W131=1,Q131<=Settings!$B$36),1,0) -> 0
A132: =Arrivals!A132 -> 2 | B132: =Arrivals!B132 -> 7 | C132: =Arrivals!F132 -> 52 | D132: =Arrivals!K132 -> 300 | E132: =D132*8/ACE_Input!S12+ACE_Input!T12 -> 24.02 | F132: =C132 -> 52 | G132: =K131 -> 146.12 | H132: =MAX(F132,G132) -> 146.12 | I132: =MOD(H132-Settings!$B$32,Settings!$B$33) -> 146.12 | J132: =IF(I132<Settings!$B$30,IF(Settings!$B$30-I132>=E132,H132,H132+(Settings!$B$30-I132)+Settings!$B$31),H132+(Settings!$B$33-I132)) -> 146.12 | K132: =J132+E132 -> 170.14 | L132: =K132 -> 170.14 | M132: =P131 -> 178.14726 | N132: =MAX(L132,M132) -> 178.14726 | O132: =Arrivals!I132 -> 2.0444372 | P132: =N132+O132 -> 180.1917 | Q132: =P132-C132 -> 128.1917 | R132: =H132-F132 -> 94.12 | S132: =J132-H132 -> 0 | T132: =N132-L132 -> 8.0072582 | U132: =R132+S132+T132 -> 102.12726 | V132: =IF(MOD(C132-Settings!$B$32,Settings!$B$33)<Settings!$B$30,"Up","Down") -> Up | W132: =IF(OR(E132>Settings!$B$30,Q132>Settings!$B$37),0,1) -> 1 | X132: =IF(AND(W132=1,Q132<=Settings!$B$36),1,0) -> 0
A133: =Arrivals!A133 -> 2 | B133: =Arrivals!B133 -> 8 | C133: =Arrivals!F133 -> 57 | D133: =Arrivals!K133 -> 300 | E133: =D133*8/ACE_Input!S13+ACE_Input!T13 -> 24.02 | F133: =C133 -> 57 | G133: =K132 -> 170.14 | H133: =MAX(F133,G133) -> 170.14 | I133: =MOD(H133-Settings!$B$32,Settings!$B$33) -> 170.14 | J133: =IF(I133<Settings!$B$30,IF(Settings!$B$30-I133>=E133,H133,H133+(Settings!$B$30-I133)+Settings!$B$31),H133+(Settings!$B$33-I133)) -> 170.14 | K133: =J133+E133 -> 194.16 | L133: =K133 -> 194.16 | M133: =P132 -> 180.1917 | N133: =MAX(L133,M133) -> 194.16 | O133: =Arrivals!I133 -> 4.3185489 | P133: =N133+O133 -> 198.47855 | Q133: =P133-C133 -> 141.47855 | R133: =H133-F133 -> 113.14 | S133: =J133-H133 -> 0 | T133: =N133-L133 -> 0 | U133: =R133+S133+T133 -> 113.14 | V133: =IF(MOD(C133-Settings!$B$32,Settings!$B$33)<Settings!$B$30,"Up","Down") -> Up | W133: =IF(OR(E133>Settings!$B$30,Q133>Settings!$B$37),0,1) -> 1 | X133: =IF(AND(W133=1,Q133<=Settings!$B$36),1,0) -> 0
A134: =Arrivals!A134 -> 2 | B134: =Arrivals!B134 -> 9 | C134: =Arrivals!F134 -> 172 | D134: =Arrivals!K134 -> 300 | E134: =D134*8/ACE_Input!S14+ACE_Input!T14 -> 24.02 | F134: =C134 -> 172 | G134: =K133 -> 194.16 | H134: =MAX(F134,G134) -> 194.16 | I134: =MOD(H134-Settings!$B$32,Settings!$B$33) -> 194.16 | J134: =IF(I134<Settings!$B$30,IF(Settings!$B$30-I134>=E134,H134,H134+(Settings!$B$30-I134)+Settings!$B$31),H134+(Settings!$B$33-I134)) -> 194.16 | K134: =J134+E134 -> 218.18 | L134: =K134 -> 218.18 | M134: =P133 -> 198.47855 | N134: =MAX(L134,M134) -> 218.18 | O134: =Arrivals!I134 -> 1.7054899 | P134: =N134+O134 -> 219.88549 | Q134: =P134-C134 -> 47.88549 | R134: =H134-F134 -> 22.16 | S134: =J134-H134 -> 0 | T134: =N134-L134 -> 0 | U134: =R134+S134+T134 -> 22.16 | V134: =IF(MOD(C134-Settings!$B$32,Settings!$B$33)<Settings!$B$30,"Up","Down") -> Up | W134: =IF(OR(E134>Settings!$B$30,Q134>Settings!$B$37),0,1) -> 1 | X134: =IF(AND(W134=1,Q134<=Settings!$B$36),1,0) -> 1
A135: =Arrivals!A135 -> 2 | B135: =Arrivals!B135 -> 10 | C135: =Arrivals!F135 -> 177 | D135: =Arrivals!K135 -> 300 | E135: =D135*8/ACE_Input!S15+ACE_Input!T15 -> 24.02 | F135: =C135 -> 177 | G135: =K134 -> 218.18 | H135: =MAX(F135,G135) -> 218.18 | I135: =MOD(H135-Settings!$B$32,Settings!$B$33) -> 218.18 | J135: =IF(I135<Settings!$B$30,IF(Settings!$B$30-I135>=E135,H135,H135+(Settings!$B$30-I135)+Settings!$B$31),H135+(Settings!$B$33-I135)) -> 218.18 | K135: =J135+E135 -> 242.2 | L135: =K135 -> 242.2 | M135: =P134 -> 219.88549 | N135: =MAX(L135,M135) -> 242.2 | O135: =Arrivals!I135 -> 0.70412258 | P135: =N135+O135 -> 242.90412 | Q135: =P135-C135 -> 65.904123 | R135: =H135-F135 -> 41.18 | S135: =J135-H135 -> 0 | T135: =N135-L135 -> 0 | U135: =R135+S135+T135 -> 41.18 | V135: =IF(MOD(C135-Settings!$B$32,Settings!$B$33)<Settings!$B$30,"Up","Down") -> Up | W135: =IF(OR(E135>Settings!$B$30,Q135>Settings!$B$37),0,1) -> 1 | X135: =IF(AND(W135=1,Q135<=Settings!$B$36),1,0) -> 1
A136: =Arrivals!A136 -> 2 | B136: =Arrivals!B136 -> 11 | C136: =Arrivals!F136 -> 182 | D136: =Arrivals!K136 -> 300 | E136: =D136*8/ACE_Input!S16+ACE_Input!T16 -> 24.02 | F136: =C136 -> 182 | G136: =K135 -> 242.2 | H136: =MAX(F136,G136) -> 242.2 | I136: =MOD(H136-Settings!$B$32,Settings!$B$33) -> 242.2 | J136: =IF(I136<Settings!$B$30,IF(Settings!$B$30-I136>=E136,H136,H136+(Settings!$B$30-I136)+Settings!$B$31),H136+(Settings!$B$33-I136)) -> 242.2 | K136: =J136+E136 -> 266.22 | L136: =K136 -> 266.22 | M136: =P135 -> 242.90412 | N136: =MAX(L136,M136) -> 266.22 | O136: =Arrivals!I136 -> 6.0473159 | P136: =N136+O136 -> 272.26732 | Q136: =P136-C136 -> 90.267316 | R136: =H136-F136 -> 60.2 | S136: =J136-H136 -> 0 | T136: =N136-L136 -> 0 | U136: =R136+S136+T136 -> 60.2 | V136: =IF(MOD(C136-Settings!$B$32,Settings!$B$33)<Settings!$B$30,"Up","Down") -> Up | W136: =IF(OR(E136>Settings!$B$30,Q136>Settings!$B$37),0,1) -> 1 | X136: =IF(AND(W136=1,Q136<=Settings!$B$36),1,0) -> 1
A137: =Arrivals!A137 -> 2 | B137: =Arrivals!B137 -> 12 | C137: =Arrivals!F137 -> 187 | D137: =Arrivals!K137 -> 300 | E137: =D137*8/ACE_Input!S17+ACE_Input!T17 -> 24.02 | F137: =C137 -> 187 | G137: =K136 -> 266.22 | H137: =MAX(F137,G137) -> 266.22 | I137: =MOD(H137-Settings!$B$32,Settings!$B$33) -> 266.22 | J137: =IF(I137<Settings!$B$30,IF(Settings!$B$30-I137>=E137,H137,H137+(Settings!$B$30-I137)+Settings!$B$31),H137+(Settings!$B$33-I137)) -> 266.22 | K137: =J137+E137 -> 290.24 | L137: =K137 -> 290.24 | M137: =P136 -> 272.26732 | N137: =MAX(L137,M137) -> 290.24 | O137: =Arrivals!I137 -> 12.023838 | P137: =N137+O137 -> 302.26384 | Q137: =P137-C137 -> 115.26384 | R137: =H137-F137 -> 79.22 | S137: =J137-H137 -> 0 | T137: =N137-L137 -> 0 | U137: =R137+S137+T137 -> 79.22 | V137: =IF(MOD(C137-Settings!$B$32,Settings!$B$33)<Settings!$B$30,"Up","Down") -> Up | W137: =IF(OR(E137>Settings!$B$30,Q137>Settings!$B$37),0,1) -> 1 | X137: =IF(AND(W137=1,Q137<=Settings!$B$36),1,0) -> 1
A138: =Arrivals!A138 -> 2 | B138: =Arrivals!B138 -> 13 | C138: =Arrivals!F138 -> 192 | D138: =Arrivals!K138 -> 300 | E138: =D138*8/ACE_Input!S18+ACE_Input!T18 -> 24.02 | F138: =C138 -> 192 | G138: =K137 -> 290.24 | H138: =MAX(F138,G138) -> 290.24 | I138: =MOD(H138-Settings!$B$32,Settings!$B$33) -> 290.24 | J138: =IF(I138<Settings!$B$30,IF(Settings!$B$30-I138>=E138,H138,H138+(Settings!$B$30-I138)+Settings!$B$31),H138+(Settings!$B$33-I138)) -> 290.24 | K138: =J138+E138 -> 314.26 | L138: =K138 -> 314.26 | M138: =P137 -> 302.26384 | N138: =MAX(L138,M138) -> 314.26 | O138: =Arrivals!I138 -> 0.89628395 | P138: =N138+O138 -> 315.15628 | Q138: =P138-C138 -> 123.15628 | R138: =H138-F138 -> 98.24 | S138: =J138-H138 -> 0 | T138: =N138-L138 -> 0 | U138: =R138+S138+T138 -> 98.24 | V138: =IF(MOD(C138-Settings!$B$32,Settings!$B$33)<Settings!$B$30,"Up","Down") -> Up | W138: =IF(OR(E138>Settings!$B$30,Q138>Settings!$B$37),0,1) -> 1 | X138: =IF(AND(W138=1,Q138<=Settings!$B$36),1,0) -> 0
... A225: =Arrivals!A225 -> 2 | B225: =Arrivals!B225 -> 100 | C225: =Arrivals!F225 -> 689 | D225: =Arrivals!K225 -> 300 | E225: =D225*8/ACE_Input!S105+ACE_Input!T105 -> 24.02 | F225: =C225 -> 689 | G225: =K224 -> 2952.06 | H225: =MAX(F225,G225) -> 2952.06 | I225: =MOD(H225-Settings!$B$32,Settings!$B$33) -> 72.06 | J225: =IF(I225<Settings!$B$30,IF(Settings!$B$30-I225>=E225,H225,H225+(Settings!$B$30-I225)+Settings!$B$31),H225+(Settings!$B$33-I225)) -> 2952.06 | K225: =J225+E225 -> 2976.08 | L225: =K225 -> 2976.08 | M225: =P224 -> 2958.1514 | N225: =MAX(L225,M225) -> 2976.08 | O225: =Arrivals!I225 -> 3.282615 | P225: =N225+O225 -> 2979.3626 | Q225: =P225-C225 -> 2290.3626 | R225: =H225-F225 -> 2263.06 | S225: =J225-H225 -> 0 | T225: =N225-L225 -> 0 | U225: =R225+S225+T225 -> 2263.06 | V225: =IF(MOD(C225-Settings!$B$32,Settings!$B$33)<Settings!$B$30,"Up","Down") -> Down | W225: =IF(OR(E225>Settings!$B$30,Q225>Settings!$B$37),0,1) -> 0 | X225: =IF(AND(W225=1,Q225<=Settings!$B$36),1,0) -> 0
A246: =Arrivals!A246 -> 3 | B246: =Arrivals!B246 -> 1 | C246: =Arrivals!F246 -> 2 | D246: =Arrivals!K246 -> 300 | E246: =D246*8/ACE_Input!S6+ACE_Input!T6 -> 24.02 | F246: =C246 -> 2 | G246: =0 -> 0 | H246: =MAX(F246,G246) -> 2 | I246: =MOD(H246-Settings!$B$32,Settings!$B$33) -> 2 | J246: =IF(I246<Settings!$B$30,IF(Settings!$B$30-I246>=E246,H246,H246+(Settings!$B$30-I246)+Settings!$B$31),H246+(Settings!$B$33-I246)) -> 2 | K246: =J246+E246 -> 26.02 | L246: =K246 -> 26.02 | M246: =0 -> 0 | N246: =MAX(L246,M246) -> 26.02 | O246: =Arrivals!I246 -> 3.2063581 | P246: =N246+O246 -> 29.226358 | Q246: =P246-C246 -> 27.226358 | R246: =H246-F246 -> 0 | S246: =J246-H246 -> 0 | T246: =N246-L246 -> 0 | U246: =R246+S246+T246 -> 0 | V246: =IF(MOD(C246-Settings!$B$32,Settings!$B$33)<Settings!$B$30,"Up","Down") -> Up | W246: =IF(OR(E246>Settings!$B$30,Q246>Settings!$B$37),0,1) -> 1 | X246: =IF(AND(W246=1,Q246<=Settings!$B$36),1,0) -> 1
A247: =Arrivals!A247 -> 3 | B247: =Arrivals!B247 -> 2 | C247: =Arrivals!F247 -> 7 | D247: =Arrivals!K247 -> 300 | E247: =D247*8/ACE_Input!S7+ACE_Input!T7 -> 24.02 | F247: =C247 -> 7 | G247: =K246 -> 26.02 | H247: =MAX(F247,G247) -> 26.02 | I247: =MOD(H247-Settings!$B$32,Settings!$B$33) -> 26.02 | J247: =IF(I247<Settings!$B$30,IF(Settings!$B$30-I247>=E247,H247,H247+(Settings!$B$30-I247)+Settings!$B$31),H247+(Settings!$B$33-I247)) -> 26.02 | K247: =J247+E247 -> 50.04 | L247: =K247 -> 50.04 | M247: =P246 -> 29.226358 | N247: =MAX(L247,M247) -> 50.04 | O247: =Arrivals!I247 -> 0.52246644 | P247: =N247+O247 -> 50.562466 | Q247: =P247-C247 -> 43.562466 | R247: =H247-F247 -> 19.02 | S247: =J247-H247 -> 0 | T247: =N247-L247 -> 0 | U247: =R247+S247+T247 -> 19.02 | V247: =IF(MOD(C247-Settings!$B$32,Settings!$B$33)<Settings!$B$30,"Up","Down") -> Up | W247: =IF(OR(E247>Settings!$B$30,Q247>Settings!$B$37),0,1) -> 1 | X247: =IF(AND(W247=1,Q247<=Settings!$B$36),1,0) -> 1
